Workbook

Sheet BASE
B3: Orientações:
L5: Semana | M5: De | N5: Até
L6: =WEEKNUM(M6) -> 1 | M6: 45292 | N6: =M6+6 -> 45298 | O6: ="De "&DAY(M6)&"/"&MONTH(M6)&" até "&DAY(N6)&"/"&MONTH(N6) -> De 1/1 até 7/1
L7: =WEEKNUM(M7) -> 2 | M7: 45298 | N7: =M7+6 -> 45304 | O7: ="De "&DAY(M7)&"/"&MONTH(M7)&" até "&DAY(N7)&"/"&MONTH(N7) -> De 7/1 até 13/1
L8: =WEEKNUM(M8) -> 3 | M8: 45305 | N8: =M8+6 -> 45311 | O8: ="De "&DAY(M8)&"/"&MONTH(M8)&" até "&DAY(N8)&"/"&MONTH(N8) -> De 14/1 até 20/1
L9: =WEEKNUM(M9) -> 4 | M9: 45312 | N9: =M9+6 -> 45318 | O9: ="De "&DAY(M9)&"/"&MONTH(M9)&" até "&DAY(N9)&"/"&MONTH(N9) -> De 21/1 até 27/1
L10: =WEEKNUM(M10) -> 5 | M10: 45319 | N10: =M10+6 -> 45325 | O10: ="De "&DAY(M10)&"/"&MONTH(M10)&" até "&DAY(N10)&"/"&MONTH(N10) -> De 28/1 até 3/2
L11: =WEEKNUM(M11) -> 6 | M11: 45326 | N11: =M11+6 -> 45332 | O11: ="De "&DAY(M11)&"/"&MONTH(M11)&" até "&DAY(N11)&"/"&MONTH(N11) -> De 4/2 até 10/2
L12: =WEEKNUM(M12) -> 7 | M12: 45333 | N12: =M12+6 -> 45339 | O12: ="De "&DAY(M12)&"/"&MONTH(M12)&" até "&DAY(N12)&"/"&MONTH(N12) -> De 11/2 até 17/2
L13: =WEEKNUM(M13) -> 8 | M13: 45340 | N13: =M13+6 -> 45346 | O13: ="De "&DAY(M13)&"/"&MONTH(M13)&" até "&DAY(N13)&"/"&MONTH(N13) -> De 18/2 até 24/2
L14: =WEEKNUM(M14) -> 9 | M14: 45347 | N14: =M14+6 -> 45353 | O14: ="De "&DAY(M14)&"/"&MONTH(M14)&" até "&DAY(N14)&"/"&MONTH(N14) -> De 25/2 até 2/3
B15: 1 | C15: segunda-feira | L15: =WEEKNUM(M15) -> 10 | M15: 45354 | N15: =M15+6 -> 45360 | O15: ="De "&DAY(M15)&"/"&MONTH(M15)&" até "&DAY(N15)&"/"&MONTH(N15) -> De 3/3 até 9/3
B16: 2 | C16: terça-feira | F16: 1 | G16: Janeiro | L16: =WEEKNUM(M16) -> 11 | M16: 45361 | N16: =M16+6 -> 45367 | O16: ="De "&DAY(M16)&"/"&MONTH(M16)&" até "&DAY(N16)&"/"&MONTH(N16) -> De 10/3 até 16/3
B17: 3 | C17: quarta-feira | F17: 2 | G17: Fevereiro | L17: =WEEKNUM(M17) -> 12 | M17: 45368 | N17: =M17+6 -> 45374 | O17: ="De "&DAY(M17)&"/"&MONTH(M17)&" até "&DAY(N17)&"/"&MONTH(N17) -> De 17/3 até 23/3
B18: 4 | C18: quinta-feira | F18: 3 | G18: Março | L18: =WEEKNUM(M18) -> 13 | M18: 45375 | N18: =M18+6 -> 45381 | O18: ="De "&DAY(M18)&"/"&MONTH(M18)&" até "&DAY(N18)&"/"&MONTH(N18) -> De 24/3 até 30/3
B19: 5 | C19: sexta-feira | F19: 4 | G19: Abril | L19: =WEEKNUM(M19) -> 14 | M19: 45382 | N19: =M19+6 -> 45388 | O19: ="De "&DAY(M19)&"/"&MONTH(M19)&" até "&DAY(N19)&"/"&MONTH(N19) -> De 31/3 até 6/4
B20: 6 | C20: sábado | F20: 5 | G20: Maio | L20: =WEEKNUM(M20) -> 15 | M20: 45389 | N20: =M20+6 -> 45395 | O20: ="De "&DAY(M20)&"/"&MONTH(M20)&" até "&DAY(N20)&"/"&MONTH(N20) -> De 7/4 até 13/4
B21: 7 | C21: domingo | F21: 6 | G21: Junho | L21: =WEEKNUM(M21) -> 16 | M21: 45396 | N21: =M21+6 -> 45402 | O21: ="De "&DAY(M21)&"/"&MONTH(M21)&" até "&DAY(N21)&"/"&MONTH(N21) -> De 14/4 até 20/4
F22: 7 | G22: Julho | L22: =WEEKNUM(M22) -> 17 | M22: 45403 | N22: =M22+6 -> 45409 | O22: ="De "&DAY(M22)&"/"&MONTH(M22)&" até "&DAY(N22)&"/"&MONTH(N22) -> De 21/4 até 27/4
F23: 8 | G23: Agosto | L23: =WEEKNUM(M23) -> 18 | M23: 45410 | N23: =M23+6 -> 45416 | O23: ="De "&DAY(M23)&"/"&MONTH(M23)&" até "&DAY(N23)&"/"&MONTH(N23) -> De 28/4 até 4/5
F24: 9 | G24: Setembro | L24: =WEEKNUM(M24) -> 19 | M24: 45417 | N24: =M24+6 -> 45423 | O24: ="De "&DAY(M24)&"/"&MONTH(M24)&" até "&DAY(N24)&"/"&MONTH(N24) -> De 5/5 até 11/5
F25: 10 | G25: Outubro | L25: =WEEKNUM(M25) -> 20 | M25: 45424 | N25: =M25+6 -> 45430 | O25: ="De "&DAY(M25)&"/"&MONTH(M25)&" até "&DAY(N25)&"/"&MONTH(N25) -> De 12/5 até 18/5
F26: 11 | G26: Novembro | L26: =WEEKNUM(M26) -> 21 | M26: 45431 | N26: =M26+6 -> 45437 | O26: ="De "&DAY(M26)&"/"&MONTH(M26)&" até "&DAY(N26)&"/"&MONTH(N26) -> De 19/5 até 25/5
F27: 12 | G27: Dezembro | L27: =WEEKNUM(M27) -> 22 | M27: 45438 | N27: =M27+6 -> 45444 | O27: ="De "&DAY(M27)&"/"&MONTH(M27)&" até "&DAY(N27)&"/"&MONTH(N27) -> De 26/5 até 1/6
L28: =WEEKNUM(M28) -> 23 | M28: 45445 | N28: =M28+6 -> 45451 | O28: ="De "&DAY(M28)&"/"&MONTH(M28)&" até "&DAY(N28)&"/"&MONTH(N28) -> De 2/6 até 8/6
L29: =WEEKNUM(M29) -> 24 | M29: 45452 | N29: =M29+6 -> 45458 | O29: ="De "&DAY(M29)&"/"&MONTH(M29)&" até "&DAY(N29)&"/"&MONTH(N29) -> De 9/6 até 15/6
L30: =WEEKNUM(M30) -> 25 | M30: 45459 | N30: =M30+6 -> 45465 | O30: ="De "&DAY(M30)&"/"&MONTH(M30)&" até "&DAY(N30)&"/"&MONTH(N30) -> De 16/6 até 22/6
L31: =WEEKNUM(M31) -> 26 | M31: 45466 | N31: =M31+6 -> 45472 | O31: ="De "&DAY(M31)&"/"&MONTH(M31)&" até "&DAY(N31)&"/"&MONTH(N31) -> De 23/6 até 29/6
L32: =WEEKNUM(M32) -> 27 | M32: 45473 | N32: =M32+6 -> 45479 | O32: ="De "&DAY(M32)&"/"&MONTH(M32)&" até "&DAY(N32)&"/"&MONTH(N32) -> De 30/6 até 6/7
L33: =WEEKNUM(M33) -> 28 | M33: 45480 | N33: =M33+6 -> 45486 | O33: ="De "&DAY(M33)&"/"&MONTH(M33)&" até "&DAY(N33)&"/"&MONTH(N33) -> De 7/7 até 13/7
L34: =WEEKNUM(M34) -> 29 | M34: 45487 | N34: =M34+6 -> 45493 | O34: ="De "&DAY(M34)&"/"&MONTH(M34)&" até "&DAY(N34)&"/"&MONTH(N34) -> De 14/7 até 20/7
L35: =WEEKNUM(M35) -> 30 | M35: 45494 | N35: =M35+6 -> 45500 | O35: ="De "&DAY(M35)&"/"&MONTH(M35)&" até "&DAY(N35)&"/"&MONTH(N35) -> De 21/7 até 27/7
L36: =WEEKNUM(M36) -> 31 | M36: 45501 | N36: =M36+6 -> 45507 | O36: ="De "&DAY(M36)&"/"&MONTH(M36)&" até "&DAY(N36)&"/"&MONTH(N36) -> De 28/7 até 3/8
L37: =WEEKNUM(M37) -> 32 | M37: 45508 | N37: =M37+6 -> 45514 | O37: ="De "&DAY(M37)&"/"&MONTH(M37)&" até "&DAY(N37)&"/"&MONTH(N37) -> De 4/8 até 10/8
L38: =WEEKNUM(M38) -> 33 | M38: 45515 | N38: =M38+6 -> 45521 | O38: ="De "&DAY(M38)&"/"&MONTH(M38)&" até "&DAY(N38)&"/"&MONTH(N38) -> De 11/8 até 17/8
L39: =WEEKNUM(M39) -> 34 | M39: 45522 | N39: =M39+6 -> 45528 | O39: ="De "&DAY(M39)&"/"&MONTH(M39)&" até "&DAY(N39)&"/"&MONTH(N39) -> De 18/8 até 24/8
... L58: =WEEKNUM(M58) -> 53 | M58: 45655 | N58: =M58+6 -> 45661 | O58: ="De "&DAY(M58)&"/"&MONTH(M58)&" até "&DAY(N58)&"/"&MONTH(N58) -> De 29/12 até 4/1

Sheet Leads
A1: Data | B1: Nome | C1: Telefone | D1: email | E1: URL | F1: utm_source | G1: utm_medium | H1: utm_term | I1: utm_content | J1: utm_campaign | K1: formato data | L1: Data Correta | M1: Telefone 8 Digitos | N1: Está no grupo?
A2: 2026-04-07T14:04:53.554Z | B2: William Barbosa | C2: 55199918096 | D2: williamandre742@gmail.com | E2: https://lp.saibai.com.br/?utm_source=MetaAds&utm_medium=ADV+-+%5BIG%5D+%5BFB%5D+%5B30%2B%5D+%5BPIEDADE+-+40KM%5D+V%C3%81RIOS&utm_campaign=07.04.2026+%5BV4%5D+%5BWB%5D+%5BLEADS-GRUPO-WHATS%5D+02&utm_content=07.04+%5BIMG%5D+%5BAD04%5D+Pedidos+abertos&utm_term=Instagram_Stories&utm_id=120248254459350155&fbclid=PAZXh0bgNhZW0BMABhZGlkAas1g0M2JftzcnRjBmFwcF9pZA81NjcwNjczNDMzNTI0MjcAAae-Pi9C5ulqTw1avKSlCfTlAiaFlEjDorhtO4cBmGvSCiUKaU-KCcm7ipMffA_aem_qVPH0fA8b5aEFs-o7UHCZA&campaign_id=120248254459350155&ad_id=120248254459370155 | F2: =IFERROR(__xludf.DUMMYFUNCTION("ARRAYFORMULA(IF($E2:$E1351="""","""",IFERROR(REGEXEXTRACT($E2:$E1351,""[?&]utm_source=([^&]+)""),"""")))"),"MetaAds") -> MetaAds | G2: =IFERROR(__xludf.DUMMYFUNCTION("ARRAYFORMULA(IF($E2:$E1351="""","""",IFERROR( REGEXREPLACE( REGEXREPLACE( SUBSTITUTE(REGEXEXTRACT($E2:$E1351,""[?&]utm_medium=([^&]+)""),""+"","" ""), ""(?i)%5B"",""[""), ""(?i)%5D"",""]"") ,""""))) "),"ADV - [IG] [FB] [30%2B] [PIEDADE - 40KM] V%C3%81RIOS") -> ADV - [IG] [FB] [30%2B] [PIEDADE - 40KM] V%C3%81RIOS | H2: =IFERROR(__xludf.DUMMYFUNCTION("ARRAYFORMULA(IF($E2:$E1351="""","""",IFERROR( REGEXREPLACE( REGEXREPLACE( SUBSTITUTE(REGEXEXTRACT($E2:$E1351,""[?&]utm_term=([^&]+)""),""+"","" ""), ""(?i)%5B"",""[""), ""(?i)%5D"",""]"") ,""""))) "),"Instagram_Stories") -> Instagram_Stories | I2: =IFERROR(__xludf.DUMMYFUNCTION("ARRAYFORMULA(IF($E2:$E1351="""","""",IFERROR( REGEXREPLACE( REGEXREPLACE( SUBSTITUTE(REGEXEXTRACT($E2:$E1351,""[?&]utm_content=([^&]+)""),""+"","" ""), ""(?i)%5B"",""[""), ""(?i)%5D"",""]"") ,""""))) "),"07.04 [IMG] [AD04] Pedidos abertos") -> 07.04 [IMG] [AD04] Pedidos abertos | J2: =IFERROR(__xludf.DUMMYFUNCTION("ARRAYFORMULA(IF($E2:$E1351="""","""",IFERROR( REGEXREPLACE( REGEXREPLACE( SUBSTITUTE(REGEXEXTRACT($E2:$E1351,""[?&]utm_campaign=([^&]+)""),""+"","" ""), ""(?i)%5B"",""[""), ""(?i)%5D"",""]"") ,""""))) "),"07.04.2026 [V4] [WB] [LEADS-GRUPO-WHATS] 02") -> 07.04.2026 [V4] [WB] [LEADS-GRUPO-WHATS] 02 | K2: =LEFT(A2,10) -> 2026-04-07 | L2: =DATE(YEAR(SUBSTITUTE(SUBSTITUTE(K2,"-","/",1),"-","/",1)),MONTH(SUBSTITUTE(SUBSTITUTE(K2,"-","/",1),"-","/",1)),DAY(SUBSTITUTE(SUBSTITUTE(K2,"-","/",1),"-","/",1))) -> 46119 | M2: =RIGHT(C2,8) -> 99918096 | N2: =IFERROR(IF(VLOOKUP(M2,'Leads no grupo Saibai'!C:C,1,FALSE)=M2,"Sim"),"Não") -> Não
A3: 2026-04-10T06:01:53.154Z | B3: lenilze pereiradaldon | C3: 55981355010 | D3: pereiradaldon@hotmail.com | E3: https://lp.saibai.com.br/?utm_source=MetaAds&utm_medium=ADV+-+%5BIG%5D+%5BFB%5D+%5B30%2B%5D+%5BPIEDADE+-+40KM%5D+V%C3%81RIOS&utm_campaign=07.04.2026+%5BV4%5D+%5BWB%5D+%5BLEADS-GRUPO-WHATS%5D+01&utm_content=07.04+%5BIMG%5D+%5BAD04%5D+Pedidos+abertos&utm_term=Instagram_Stories&utm_id=120247452154580155&fbclid=PAZXh0bgNhZW0BMABhZGlkAas0bAfOj7tzcnRjBmFwcF9pZA81NjcwNjczNDMzNTI0MjcAAafhAJfazzKXYAWRJ1dJ-3Yx8wr-kjkNLqLkYIgbyMCz1Rf1plENwmmd43T_YA_aem_KZY9Eo1RU3GvOgoqY-w8hw&campaign_id=120247452154580155&ad_id=120247452938090155 | F3: =IFERROR(__xludf.DUMMYFUNCTION("""COMPUTED_VALUE"""),"MetaAds") -> MetaAds | G3: =IFERROR(__xludf.DUMMYFUNCTION("""COMPUTED_VALUE"""),"ADV - [IG] [FB] [30%2B] [PIEDADE - 40KM] V%C3%81RIOS") -> ADV - [IG] [FB] [30%2B] [PIEDADE - 40KM] V%C3%81RIOS | H3: =IFERROR(__xludf.DUMMYFUNCTION("""COMPUTED_VALUE"""),"Instagram_Stories") -> Instagram_Stories | I3: =IFERROR(__xludf.DUMMYFUNCTION("""COMPUTED_VALUE"""),"07.04 [IMG] [AD04] Pedidos abertos") -> 07.04 [IMG] [AD04] Pedidos abertos | J3: =IFERROR(__xludf.DUMMYFUNCTION("""COMPUTED_VALUE"""),"07.04.2026 [V4] [WB] [LEADS-GRUPO-WHATS] 01") -> 07.04.2026 [V4] [WB] [LEADS-GRUPO-WHATS] 01 | K3: =LEFT(A3,10) -> 2026-04-10 | L3: =DATE(YEAR(SUBSTITUTE(SUBSTITUTE(K3,"-","/",1),"-","/",1)),MONTH(SUBSTITUTE(SUBSTITUTE(K3,"-","/",1),"-","/",1)),DAY(SUBSTITUTE(SUBSTITUTE(K3,"-","/",1),"-","/",1))) -> 46122 | M3: =RIGHT(C3,8) -> 81355010 | N3: =IFERROR(IF(VLOOKUP(M3,'Leads no grupo Saibai'!C:C,1,FALSE)=M3,"Sim"),"Não") -> Não
A4: 2026-04-10T06:02:30.692Z | B4: lenilze pereiradaldon | C4: 55981355010 | D4: pereiradaldon@hotmail.com | E4: https://lp.saibai.com.br/?utm_source=MetaAds&utm_medium=ADV+-+%5BIG%5D+%5BFB%5D+%5B30%2B%5D+%5BPIEDADE+-+40KM%5D+V%C3%81RIOS&utm_campaign=07.04.2026+%5BV4%5D+%5BWB%5D+%5BLEADS-GRUPO-WHATS%5D+01&utm_content=07.04+%5BIMG%5D+%5BAD04%5D+Pedidos+abertos&utm_term=Instagram_Stories&utm_id=120247452154580155&fbclid=PAZXh0bgNhZW0BMABhZGlkAas0bAfOj7tzcnRjBmFwcF9pZA81NjcwNjczNDMzNTI0MjcAAafhAJfazzKXYAWRJ1dJ-3Yx8wr-kjkNLqLkYIgbyMCz1Rf1plENwmmd43T_YA_aem_KZY9Eo1RU3GvOgoqY-w8hw&campaign_id=120247452154580155&ad_id=120247452938090155 | F4: =IFERROR(__xludf.DUMMYFUNCTION("""COMPUTED_VALUE"""),"MetaAds") -> MetaAds | G4: =IFERROR(__xludf.DUMMYFUNCTION("""COMPUTED_VALUE"""),"ADV - [IG] [FB] [30%2B] [PIEDADE - 40KM] V%C3%81RIOS") -> ADV - [IG] [FB] [30%2B] [PIEDADE - 40KM] V%C3%81RIOS | H4: =IFERROR(__xludf.DUMMYFUNCTION("""COMPUTED_VALUE"""),"Instagram_Stories") -> Instagram_Stories | I4: =IFERROR(__xludf.DUMMYFUNCTION("""COMPUTED_VALUE"""),"07.04 [IMG] [AD04] Pedidos abertos") -> 07.04 [IMG] [AD04] Pedidos abertos | J4: =IFERROR(__xludf.DUMMYFUNCTION("""COMPUTED_VALUE"""),"07.04.2026 [V4] [WB] [LEADS-GRUPO-WHATS] 01") -> 07.04.2026 [V4] [WB] [LEADS-GRUPO-WHATS] 01 | K4: =LEFT(A4,10) -> 2026-04-10 | L4: =DATE(YEAR(SUBSTITUTE(SUBSTITUTE(K4,"-","/",1),"-","/",1)),MONTH(SUBSTITUTE(SUBSTITUTE(K4,"-","/",1),"-","/",1)),DAY(SUBSTITUTE(SUBSTITUTE(K4,"-","/",1),"-","/",1))) -> 46122 | M4: =RIGHT(C4,8) -> 81355010 | N4: =IFERROR(IF(VLOOKUP(M4,'Leads no grupo Saibai'!C:C,1,FALSE)=M4,"Sim"),"Não") -> Não
A5: 2026-04-10T07:47:42.252Z | B5: ODILON BUENO | C5: 15997577218 | D5: odilon.bueno@autoescolaabc.com.br | E5: https://lp.saibai.com.br/?utm_source=MetaAds&utm_medium=ADV+-+%5BIG%5D+%5BFB%5D+%5B30%2B%5D+%5BPIEDADE+-+40KM%5D+V%C3%81RIOS&utm_campaign=07.04.2026+%5BV4%5D+%5BWB%5D+%5BLEADS-GRUPO-WHATS%5D+01&utm_content=07.04+%5BIMG%5D+%5BAD04%5D+Pedidos+abertos&utm_term=Instagram_Stories&utm_id=120247452154580155&fbclid=PAZXh0bgNhZW0BMABhZGlkAas0bAW7ZytzcnRjBmFwcF9pZA8xMjQwMjQ1NzQyODc0MTQAAaeEbScr7uc5Bw7yQlSg97yg1D1SgKabzfOnG166KAsAcqQyKH8mzWdxuDGDaA_aem_DqH-FubtkiHGvX0LGSaFzw&campaign_id=120247452154580155&ad_id=120247452938090155 | F5: =IFERROR(__xludf.DUMMYFUNCTION("""COMPUTED_VALUE"""),"MetaAds") -> MetaAds | G5: =IFERROR(__xludf.DUMMYFUNCTION("""COMPUTED_VALUE"""),"ADV - [IG] [FB] [30%2B] [PIEDADE - 40KM] V%C3%81RIOS") -> ADV - [IG] [FB] [30%2B] [PIEDADE - 40KM] V%C3%81RIOS | H5: =IFERROR(__xludf.DUMMYFUNCTION("""COMPUTED_VALUE"""),"Instagram_Stories") -> Instagram_Stories | I5: =IFERROR(__xludf.DUMMYFUNCTION("""COMPUTED_VALUE"""),"07.04 [IMG] [AD04] Pedidos abertos") -> 07.04 [IMG] [AD04] Pedidos abertos | J5: =IFERROR(__xludf.DUMMYFUNCTION("""COMPUTED_VALUE"""),"07.04.2026 [V4] [WB] [LEADS-GRUPO-WHATS] 01") -> 07.04.2026 [V4] [WB] [LEADS-GRUPO-WHATS] 01 | K5: =LEFT(A5,10) -> 2026-04-10 | L5: =DATE(YEAR(SUBSTITUTE(SUBSTITUTE(K5,"-","/",1),"-","/",1)),MONTH(SUBSTITUTE(SUBSTITUTE(K5,"-","/",1),"-","/",1)),DAY(SUBSTITUTE(SUBSTITUTE(K5,"-","/",1),"-","/",1))) -> 46122 | M5: =RIGHT(C5,8) -> 97577218 | N5: =IFERROR(IF(VLOOKUP(M5,'Leads no grupo Saibai'!C:C,1,FALSE)=M5,"Sim"),"Não") -> Sim
A6: 2026-04-10T08:05:20.787Z | B6: andrea pedreira | C6: 15996014055 | D6: andreapedreira15@gmail.com | E6: https://lp.saibai.com.br/?utm_source=MetaAds&utm_medium=ADV+-+%5BIG%5D+%5BFB%5D+%5B30%2B%5D+%5BPIEDADE+-+40KM%5D+V%C3%81RIOS&utm_campaign=07.04.2026+%5BV4%5D+%5BWB%5D+%5BLEADS-GRUPO-WHATS%5D+02&utm_content=07.04+%5BIMG%5D+%5BAD04%5D+Pedidos+abertos&utm_term=Instagram_Stories&utm_id=120248254459350155&fbclid=PAZXh0bgNhZW0BMABhZGlkAas1g0M2JftzcnRjBmFwcF9pZA81NjcwNjczNDMzNTI0MjcAAae-Pi9C5ulqTw1avKSlCfTlAiaFlEjDorhtO4cBmGvSCiUKaU-KCcm7ipMffA_aem_qVPH0fA8b5aEFs-o7UHCZA&campaign_id=120248254459350155&ad_id=120248254459370155 | F6: =IFERROR(__xludf.DUMMYFUNCTION("""COMPUTED_VALUE"""),"MetaAds") -> MetaAds | G6: =IFERROR(__xludf.DUMMYFUNCTION("""COMPUTED_VALUE"""),"ADV - [IG] [FB] [30%2B] [PIEDADE - 40KM] V%C3%81RIOS") -> ADV - [IG] [FB] [30%2B] [PIEDADE - 40KM] V%C3%81RIOS | H6: =IFERROR(__xludf.DUMMYFUNCTION("""COMPUTED_VALUE"""),"Instagram_Stories") -> Instagram_Stories | I6: =IFERROR(__xludf.DUMMYFUNCTION("""COMPUTED_VALUE"""),"07.04 [IMG] [AD04] Pedidos abertos") -> 07.04 [IMG] [AD04] Pedidos abertos | J6: =IFERROR(__xludf.DUMMYFUNCTION("""COMPUTED_VALUE"""),"07.04.2026 [V4] [WB] [LEADS-GRUPO-WHATS] 02") -> 07.04.2026 [V4] [WB] [LEADS-GRUPO-WHATS] 02 | K6: =LEFT(A6,10) -> 2026-04-10 | L6: =DATE(YEAR(SUBSTITUTE(SUBSTITUTE(K6,"-","/",1),"-","/",1)),MONTH(SUBSTITUTE(SUBSTITUTE(K6,"-","/",1),"-","/",1)),DAY(SUBSTITUTE(SUBSTITUTE(K6,"-","/",1),"-","/",1))) -> 46122 | M6: =RIGHT(C6,8) -> 96014055 | N6: =IFERROR(IF(VLOOKUP(M6,'Leads no grupo Saibai'!C:C,1,FALSE)=M6,"Sim"),"Não") -> Sim
A7: 2026-04-10T08:15:22.674Z | B7: Bruno Rocha | C7: 15997000778 | D7: brunokr77@hotmail.com | E7: https://lp.saibai.com.br/?utm_source=MetaAds&utm_medium=ADV+-+%5BIG%5D+%5BFB%5D+%5B30%2B%5D+%5BPIEDADE+-+40KM%5D+V%C3%81RIOS&utm_campaign=07.04.2026+%5BV4%5D+%5BWB%5D+%5BLEADS-GRUPO-WHATS%5D+01&utm_content=07.04+%5BIMG%5D+%5BAD04%5D+Pedidos+abertos&utm_term=Instagram_Stories&utm_id=120247452154580155&fbclid=PAZXh0bgNhZW0BMABhZGlkAas0bAW7ZytzcnRjBmFwcF9pZA81NjcwNjczNDMzNTI0MjcAAafkHLECCqoGBZ18nJzv-QLbVeYATsNjV39JHPvcC8QjSrG8C4kR93mDt3Yv7w_aem_uFBmSIdVrdndo335G3WZYg&campaign_id=120247452154580155&ad_id=120247452938090155 | F7: =IFERROR(__xludf.DUMMYFUNCTION("""COMPUTED_VALUE"""),"MetaAds") -> MetaAds | G7: =IFERROR(__xludf.DUMMYFUNCTION("""COMPUTED_VALUE"""),"ADV - [IG] [FB] [30%2B] [PIEDADE - 40KM] V%C3%81RIOS") -> ADV - [IG] [FB] [30%2B] [PIEDADE - 40KM] V%C3%81RIOS | H7: =IFERROR(__xludf.DUMMYFUNCTION("""COMPUTED_VALUE"""),"Instagram_Stories") -> Instagram_Stories | I7: =IFERROR(__xludf.DUMMYFUNCTION("""COMPUTED_VALUE"""),"07.04 [IMG] [AD04] Pedidos abertos") -> 07.04 [IMG] [AD04] Pedidos abertos | J7: =IFERROR(__xludf.DUMMYFUNCTION("""COMPUTED_VALUE"""),"07.04.2026 [V4] [WB] [LEADS-GRUPO-WHATS] 01") -> 07.04.2026 [V4] [WB] [LEADS-GRUPO-WHATS] 01 | K7: =LEFT(A7,10) -> 2026-04-10 | L7: =DATE(YEAR(SUBSTITUTE(SUBSTITUTE(K7,"-","/",1),"-","/",1)),MONTH(SUBSTITUTE(SUBSTITUTE(K7,"-","/",1),"-","/",1)),DAY(SUBSTITUTE(SUBSTITUTE(K7,"-","/",1),"-","/",1))) -> 46122 | M7: =RIGHT(C7,8) -> 97000778 | N7: =IFERROR(IF(VLOOKUP(M7,'Leads no grupo Saibai'!C:C,1,FALSE)=M7,"Sim"),"Não") -> Sim
A8: 2026-04-10T09:23:53.934Z | B8: olga cipriani | C8: 11953038767 | D8: olga.ciprianis1@gmail.com | E8: https://lp.saibai.com.br/?utm_source=MetaAds&utm_medium=ADV+-+%5BIG%5D+%5BFB%5D+%5B30%2B%5D+%5BPIEDADE+-+40KM%5D+V%C3%81RIOS&utm_campaign=07.04.2026+%5BV4%5D+%5BWB%5D+%5BLEADS-GRUPO-WHATS%5D+01&utm_content=07.04+%5BIMG%5D+%5BAD04%5D+Pedidos+abertos&utm_term=Instagram_Feed&utm_id=120247452154580155&fbclid=PAZXh0bgNhZW0BMABhZGlkAas0bAfOj7tzcnRjBmFwcF9pZA81NjcwNjczNDMzNTI0MjcAAafyRYo2_90IpooxKqGA8j9F7ok0lGg4kYeY5dFCdA92b9PibOmsDkGjC-ap0A_aem_uKOuzVKmqVAxU81O_pOA4w&campaign_id=120247452154580155&ad_id=120247452938090155 | F8: =IFERROR(__xludf.DUMMYFUNCTION("""COMPUTED_VALUE"""),"MetaAds") -> MetaAds | G8: =IFERROR(__xludf.DUMMYFUNCTION("""COMPUTED_VALUE"""),"ADV - [IG] [FB] [30%2B] [PIEDADE - 40KM] V%C3%81RIOS") -> ADV - [IG] [FB] [30%2B] [PIEDADE - 40KM] V%C3%81RIOS | H8: =IFERROR(__xludf.DUMMYFUNCTION("""COMPUTED_VALUE"""),"Instagram_Feed") -> Instagram_Feed | I8: =IFERROR(__xludf.DUMMYFUNCTION("""COMPUTED_VALUE"""),"07.04 [IMG] [AD04] Pedidos abertos") -> 07.04 [IMG] [AD04] Pedidos abertos | J8: =IFERROR(__xludf.DUMMYFUNCTION("""COMPUTED_VALUE"""),"07.04.2026 [V4] [WB] [LEADS-GRUPO-WHATS] 01") -> 07.04.2026 [V4] [WB] [LEADS-GRUPO-WHATS] 01 | K8: =LEFT(A8,10) -> 2026-04-10 | L8: =DATE(YEAR(SUBSTITUTE(SUBSTITUTE(K8,"-","/",1),"-","/",1)),MONTH(SUBSTITUTE(SUBSTITUTE(K8,"-","/",1),"-","/",1)),DAY(SUBSTITUTE(SUBSTITUTE(K8,"-","/",1),"-","/",1))) -> 46122 | M8: =RIGHT(C8,8) -> 53038767 | N8: =IFERROR(IF(VLOOKUP(M8,'Leads no grupo Saibai'!C:C,1,FALSE)=M8,"Sim"),"Não") -> Sim
A9: 2026-04-10T10:33:01.775Z | B9: Luciane Campos | C9: 15991920716 | D9: lucamposmoraes79@gmail.com | E9: https://lp.saibai.com.br/?utm_source=MetaAds&utm_medium=ADV+-+%5BIG%5D+%5BFB%5D+%5B30%2B%5D+%5BPIEDADE+-+40KM%5D+V%C3%81RIOS&utm_campaign=07.04.2026+%5BV4%5D+%5BWB%5D+%5BLEADS-GRUPO-WHATS%5D+01&utm_content=07.04+%5BIMG%5D+%5BAD04%5D+Pedidos+abertos&utm_term=Instagram_Feed&utm_id=120247452154580155&fbclid=PAZXh0bgNhZW0BMABhZGlkAas0bAfOj7tzcnRjBmFwcF9pZA8xMjQwMjQ1NzQyODc0MTQAAafi41HK2ZIMpCodLrKzNuhsjsToZTCTU5UhLxL0mH24dy3pVPGEDwosjG7NdA_aem_lg2YQ_WXpZaScY1I4fUjVg&campaign_id=120247452154580155&ad_id=120247452938090155 | F9: =IFERROR(__xludf.DUMMYFUNCTION("""COMPUTED_VALUE"""),"MetaAds") -> MetaAds | G9: =IFERROR(__xludf.DUMMYFUNCTION("""COMPUTED_VALUE"""),"ADV - [IG] [FB] [30%2B] [PIEDADE - 40KM] V%C3%81RIOS") -> ADV - [IG] [FB] [30%2B] [PIEDADE - 40KM] V%C3%81RIOS | H9: =IFERROR(__xludf.DUMMYFUNCTION("""COMPUTED_VALUE"""),"Instagram_Feed") -> Instagram_Feed | I9: =IFERROR(__xludf.DUMMYFUNCTION("""COMPUTED_VALUE"""),"07.04 [IMG] [AD04] Pedidos abertos") -> 07.04 [IMG] [AD04] Pedidos abertos | J9: =IFERROR(__xludf.DUMMYFUNCTION("""COMPUTED_VALUE"""),"07.04.2026 [V4] [WB] [LEADS-GRUPO-WHATS] 01") -> 07.04.2026 [V4] [WB] [LEADS-GRUPO-WHATS] 01 | K9: =LEFT(A9,10) -> 2026-04-10 | L9: =DATE(YEAR(SUBSTITUTE(SUBSTITUTE(K9,"-","/",1),"-","/",1)),MONTH(SUBSTITUTE(SUBSTITUTE(K9,"-","/",1),"-","/",1)),DAY(SUBSTITUTE(SUBSTITUTE(K9,"-","/",1),"-","/",1))) -> 46122 | M9: =RIGHT(C9,8) -> 91920716 | N9: =IFERROR(IF(VLOOKUP(M9,'Leads no grupo Saibai'!C:C,1,FALSE)=M9,"Sim"),"Não") -> Sim
A10: 2026-04-10T11:58:07.924Z | B10: Mônica Maia | C10: 15991729665 | D10: mo_adv@hotmail.com | E10: https://lp.saibai.com.br/?utm_source=MetaAds&utm_medium=ADV+-+%5BIG%5D+%5BFB%5D+%5B30%2B%5D+%5BPIEDADE+-+40KM%5D+V%C3%81RIOS&utm_campaign=07.04.2026+%5BV4%5D+%5BWB%5D+%5BLEADS-GRUPO-WHATS%5D+01&utm_content=07.04+%5BIMG%5D+%5BAD04%5D+Pedidos+abertos&utm_term=Instagram_Stories&utm_id=120247452154580155&fbclid=PAZXh0bgNhZW0BMABhZGlkAas0bAW7ZytzcnRjBmFwcF9pZA8xMjQwMjQ1NzQyODc0MTQAAad7D3Tpmc6ccGNpA-McIPCMZd0f9qVYEXWoYdN1W4ZFVotKQqsWKVDNYNCYpQ_aem_f_csxX1Gm0Or_AybL4W4YQ&campaign_id=120247452154580155&ad_id=120247452938090155 | F10: =IFERROR(__xludf.DUMMYFUNCTION("""COMPUTED_VALUE"""),"MetaAds") -> MetaAds | G10: =IFERROR(__xludf.DUMMYFUNCTION("""COMPUTED_VALUE"""),"ADV - [IG] [FB] [30%2B] [PIEDADE - 40KM] V%C3%81RIOS") -> ADV - [IG] [FB] [30%2B] [PIEDADE - 40KM] V%C3%81RIOS | H10: =IFERROR(__xludf.DUMMYFUNCTION("""COMPUTED_VALUE"""),"Instagram_Stories") -> Instagram_Stories | I10: =IFERROR(__xludf.DUMMYFUNCTION("""COMPUTED_VALUE"""),"07.04 [IMG] [AD04] Pedidos abertos") -> 07.04 [IMG] [AD04] Pedidos abertos | J10: =IFERROR(__xludf.DUMMYFUNCTION("""COMPUTED_VALUE"""),"07.04.2026 [V4] [WB] [LEADS-GRUPO-WHATS] 01") -> 07.04.2026 [V4] [WB] [LEADS-GRUPO-WHATS] 01 | K10: =LEFT(A10,10) -> 2026-04-10 | L10: =DATE(YEAR(SUBSTITUTE(SUBSTITUTE(K10,"-","/",1),"-","/",1)),MONTH(SUBSTITUTE(SUBSTITUTE(K10,"-","/",1),"-","/",1)),DAY(SUBSTITUTE(SUBSTITUTE(K10,"-","/",1),"-","/",1))) -> 46122 | M10: =RIGHT(C10,8) -> 91729665 | N10: =IFERROR(IF(VLOOKUP(M10,'Leads no grupo Saibai'!C:C,1,FALSE)=M10,"Sim"),"Não") -> Sim
A11: 2026-04-10T12:02:03.351Z | B11: Jose Francisco Gabriotti | C11: 55159815097 | D11: josefranciscogabriotti@gmail.com | E11: https://lp.saibai.com.br/?utm_source=MetaAds&utm_medium=ADV+-+%5BIG%5D+%5BFB%5D+%5B30%2B%5D+%5BPIEDADE+-+40KM%5D+V%C3%81RIOS&utm_campaign=07.04.2026+%5BV4%5D+%5BWB%5D+%5BLEADS-GRUPO-WHATS%5D+01&utm_content=07.04+%5BIMG%5D+%5BAD04%5D+Pedidos+abertos&utm_term=Instagram_Feed&utm_id=120247452154580155&fbclid=PAZXh0bgNhZW0BMABhZGlkAas0bAW7ZytzcnRjBmFwcF9pZA81NjcwNjczNDMzNTI0MjcAAafxyRYJv5YVi6CifZTmm9PDHuPEq1eWVJVRDRYd_BrqVy2ZKPmtaL_Dv5NSEA_aem_6CgVnOQ6Cl01jRgfKwTMPg&campaign_id=120247452154580155&ad_id=120247452938090155 | F11: =IFERROR(__xludf.DUMMYFUNCTION("""COMPUTED_VALUE"""),"MetaAds") -> MetaAds | G11: =IFERROR(__xludf.DUMMYFUNCTION("""COMPUTED_VALUE"""),"ADV - [IG] [FB] [30%2B] [PIEDADE - 40KM] V%C3%81RIOS") -> ADV - [IG] [FB] [30%2B] [PIEDADE - 40KM] V%C3%81RIOS | H11: =IFERROR(__xludf.DUMMYFUNCTION("""COMPUTED_VALUE"""),"Instagram_Feed") -> Instagram_Feed | I11: =IFERROR(__xludf.DUMMYFUNCTION("""COMPUTED_VALUE"""),"07.04 [IMG] [AD04] Pedidos abertos") -> 07.04 [IMG] [AD04] Pedidos abertos | J11: =IFERROR(__xludf.DUMMYFUNCTION("""COMPUTED_VALUE"""),"07.04.2026 [V4] [WB] [LEADS-GRUPO-WHATS] 01") -> 07.04.2026 [V4] [WB] [LEADS-GRUPO-WHATS] 01 | K11: =LEFT(A11,10) -> 2026-04-10 | L11: =DATE(YEAR(SUBSTITUTE(SUBSTITUTE(K11,"-","/",1),"-","/",1)),MONTH(SUBSTITUTE(SUBSTITUTE(K11,"-","/",1),"-","/",1)),DAY(SUBSTITUTE(SUBSTITUTE(K11,"-","/",1),"-","/",1))) -> 46122 | M11: =RIGHT(C11,8) -> 59815097 | N11: =IFERROR(IF(VLOOKUP(M11,'Leads no grupo Saibai'!C:C,1,FALSE)=M11,"Sim"),"Não") -> Não
A12: 2026-04-10T12:07:26.957Z | B12: Eliana Banhete | C12: 55159978270 | D12: lica1755@gmail.com | E12: https://lp.saibai.com.br/?utm_source=MetaAds&utm_medium=ADV+-+%5BIG%5D+%5BFB%5D+%5B30%2B%5D+%5BPIEDADE+-+40KM%5D+V%C3%81RIOS&utm_campaign=07.04.2026+%5BV4%5D+%5BWB%5D+%5BLEADS-GRUPO-WHATS%5D+02&utm_content=07.04+%5BIMG%5D+%5BAD04%5D+Pedidos+abertos&utm_term=Instagram_Stories&utm_id=120248254459350155&fbclid=PAZXh0bgNhZW0BMABhZGlkAas1g0M2JftzcnRjBmFwcF9pZA81NjcwNjczNDMzNTI0MjcAAae-Pi9C5ulqTw1avKSlCfTlAiaFlEjDorhtO4cBmGvSCiUKaU-KCcm7ipMffA_aem_qVPH0fA8b5aEFs-o7UHCZA&campaign_id=120248254459350155&ad_id=120248254459370155 | F12: =IFERROR(__xludf.DUMMYFUNCTION("""COMPUTED_VALUE"""),"MetaAds") -> MetaAds | G12: =IFERROR(__xludf.DUMMYFUNCTION("""COMPUTED_VALUE"""),"ADV - [IG] [FB] [30%2B] [PIEDADE - 40KM] V%C3%81RIOS") -> ADV - [IG] [FB] [30%2B] [PIEDADE - 40KM] V%C3%81RIOS | H12: =IFERROR(__xludf.DUMMYFUNCTION("""COMPUTED_VALUE"""),"Instagram_Stories") -> Instagram_Stories | I12: =IFERROR(__xludf.DUMMYFUNCTION("""COMPUTED_VALUE"""),"07.04 [IMG] [AD04] Pedidos abertos") -> 07.04 [IMG] [AD04] Pedidos abertos | J12: =IFERROR(__xludf.DUMMYFUNCTION("""COMPUTED_VALUE"""),"07.04.2026 [V4] [WB] [LEADS-GRUPO-WHATS] 02") -> 07.04.2026 [V4] [WB] [LEADS-GRUPO-WHATS] 02 | K12: =LEFT(A12,10) -> 2026-04-10 | L12: =DATE(YEAR(SUBSTITUTE(SUBSTITUTE(K12,"-","/",1),"-","/",1)),MONTH(SUBSTITUTE(SUBSTITUTE(K12,"-","/",1),"-","/",1)),DAY(SUBSTITUTE(SUBSTITUTE(K12,"-","/",1),"-","/",1))) -> 46122 | M12: =RIGHT(C12,8) -> 59978270 | N12: =IFERROR(IF(VLOOKUP(M12,'Leads no grupo Saibai'!C:C,1,FALSE)=M12,"Sim"),"Não") -> Não
A13: 2026-04-10T15:53:47.927Z | B13: Clara Espim | C13: 15996081643 | D13: claraespimag@gmail.com | E13: https://lp.saibai.com.br/?utm_source=MetaAds&utm_medium=ADV+-+%5BIG%5D+%5BFB%5D+%5B30%2B%5D+%5BPIEDADE+-+40KM%5D+V%C3%81RIOS&utm_campaign=07.04.2026+%5BV4%5D+%5BWB%5D+%5BLEADS-GRUPO-WHATS%5D+01&utm_content=07.04+%5BIMG%5D+%5BAD04%5D+Pedidos+abertos&utm_term=Instagram_Stories&utm_id=120247452154580155&fbclid=PAZXh0bgNhZW0BMABhZGlkAas0bAW7ZytzcnRjBmFwcF9pZA8xMjQwMjQ1NzQyODc0MTQAAaf9HoTAkjFD5tL3oGfq3V2vAUSfWXAjWQtyelDOo5n9yRZWKbckaeEdc-D0QA_aem_5ljKjwEKKrb7uhuKqWsOAA&campaign_id=120247452154580155&ad_id=120247452938090155 | F13: =IFERROR(__xludf.DUMMYFUNCTION("""COMPUTED_VALUE"""),"MetaAds") -> MetaAds | G13: =IFERROR(__xludf.DUMMYFUNCTION("""COMPUTED_VALUE"""),"ADV - [IG] [FB] [30%2B] [PIEDADE - 40KM] V%C3%81RIOS") -> ADV - [IG] [FB] [30%2B] [PIEDADE - 40KM] V%C3%81RIOS | H13: =IFERROR(__xludf.DUMMYFUNCTION("""COMPUTED_VALUE"""),"Instagram_Stories") -> Instagram_Stories | I13: =IFERROR(__xludf.DUMMYFUNCTION("""COMPUTED_VALUE"""),"07.04 [IMG] [AD04] Pedidos abertos") -> 07.04 [IMG] [AD04] Pedidos abertos | J13: =IFERROR(__xludf.DUMMYFUNCTION("""COMPUTED_VALUE"""),"07.04.2026 [V4] [WB] [LEADS-GRUPO-WHATS] 01") -> 07.04.2026 [V4] [WB] [LEADS-GRUPO-WHATS] 01 | K13: =LEFT(A13,10) -> 2026-04-10 | L13: =DATE(YEAR(SUBSTITUTE(SUBSTITUTE(K13,"-","/",1),"-","/",1)),MONTH(SUBSTITUTE(SUBSTITUTE(K13,"-","/",1),"-","/",1)),DAY(SUBSTITUTE(SUBSTITUTE(K13,"-","/",1),"-","/",1))) -> 46122 | M13: =RIGHT(C13,8) -> 96081643 | N13: =IFERROR(IF(VLOOKUP(M13,'Leads no grupo Saibai'!C:C,1,FALSE)=M13,"Sim"),"Não") -> Sim
A14: 2026-04-10T16:57:01.367Z | B14: Zenaide | C14: 15998141671 | D14: zenaidealmeida_cruz@hotmail.com | E14: https://lp.saibai.com.br/?utm_source=MetaAds&utm_medium=ADV+-+%5BIG%5D+%5BFB%5D+%5B30%2B%5D+%5BPIEDADE+-+40KM%5D+V%C3%81RIOS&utm_campaign=07.04.2026+%5BV4%5D+%5BWB%5D+%5BLEADS-GRUPO-WHATS%5D+01&utm_content=07.04+%5BIMG%5D+%5BAD04%5D+Pedidos+abertos&utm_term=Facebook_Mobile_Feed&fbclid=IwZXh0bgNhZW0BMABhZGlkAas0bAW7ZytzcnRjBmFwcF9pZAwzNTA2ODU1MzE3MjgAAR6g8AzhzvHcJQK1SOp1uFCRSyvd3MHHBZ8f9IGnRmrxu4mx_8AqQ6_KgP6BNQ_aem_k1pDRVarn87y__oJ77WQJg&campaign_id=120247452154580155&ad_id=120247452938090155&utm_id=120247452154580155 | F14: =IFERROR(__xludf.DUMMYFUNCTION("""COMPUTED_VALUE"""),"MetaAds") -> MetaAds | G14: =IFERROR(__xludf.DUMMYFUNCTION("""COMPUTED_VALUE"""),"ADV - [IG] [FB] [30%2B] [PIEDADE - 40KM] V%C3%81RIOS") -> ADV - [IG] [FB] [30%2B] [PIEDADE - 40KM] V%C3%81RIOS | H14: =IFERROR(__xludf.DUMMYFUNCTION("""COMPUTED_VALUE"""),"Facebook_Mobile_Feed") -> Facebook_Mobile_Feed | I14: =IFERROR(__xludf.DUMMYFUNCTION("""COMPUTED_VALUE"""),"07.04 [IMG] [AD04] Pedidos abertos") -> 07.04 [IMG] [AD04] Pedidos abertos | J14: =IFERROR(__xludf.DUMMYFUNCTION("""COMPUTED_VALUE"""),"07.04.2026 [V4] [WB] [LEADS-GRUPO-WHATS] 01") -> 07.04.2026 [V4] [WB] [LEADS-GRUPO-WHATS] 01 | K14: =LEFT(A14,10) -> 2026-04-10 | L14: =DATE(YEAR(SUBSTITUTE(SUBSTITUTE(K14,"-","/",1),"-","/",1)),MONTH(SUBSTITUTE(SUBSTITUTE(K14,"-","/",1),"-","/",1)),DAY(SUBSTITUTE(SUBSTITUTE(K14,"-","/",1),"-","/",1))) -> 46122 | M14: =RIGHT(C14,8) -> 98141671 | N14: =IFERROR(IF(VLOOKUP(M14,'Leads no grupo Saibai'!C:C,1,FALSE)=M14,"Sim"),"Não") -> Sim
A15: 2026-04-11T07:24:44.570Z | B15: Vivian Santos | C15: 15981773711 | D15: vifirmino@gmail.com | E15: https://lp.saibai.com.br/?utm_source=MetaAds&utm_medium=ADV+-+%5BIG%5D+%5BFB%5D+%5B30%2B%5D+%5BPIEDADE+-+40KM%5D+V%C3%81RIOS&utm_campaign=07.04.2026+%5BV4%5D+%5BWB%5D+%5BLEADS-GRUPO-WHATS%5D+01&utm_content=07.04+%5BIMG%5D+%5BAD04%5D+Pedidos+abertos&utm_term=Facebook_Mobile_Feed&fbclid=IwZXh0bgNhZW0BMABhZGlkAas0bAW7ZytzcnRjBmFwcF9pZAwzNTA2ODU1MzE3MjgAAR7oOS-K5DK8biC4NSQcjww51xnw6L40H33qaUuDsve2ZTcbINbSQWzhv2fb0w_aem_KtoMuAMvfgLLnhsIHNpLgw&campaign_id=120247452154580155&ad_id=120247452938090155&utm_id=120247452154580155 | F15: =IFERROR(__xludf.DUMMYFUNCTION("""COMPUTED_VALUE"""),"MetaAds") -> MetaAds | G15: =IFERROR(__xludf.DUMMYFUNCTION("""COMPUTED_VALUE"""),"ADV - [IG] [FB] [30%2B] [PIEDADE - 40KM] V%C3%81RIOS") -> ADV - [IG] [FB] [30%2B] [PIEDADE - 40KM] V%C3%81RIOS | H15: =IFERROR(__xludf.DUMMYFUNCTION("""COMPUTED_VALUE"""),"Facebook_Mobile_Feed") -> Facebook_Mobile_Feed | I15: =IFERROR(__xludf.DUMMYFUNCTION("""COMPUTED_VALUE"""),"07.04 [IMG] [AD04] Pedidos abertos") -> 07.04 [IMG] [AD04] Pedidos abertos | J15: =IFERROR(__xludf.DUMMYFUNCTION("""COMPUTED_VALUE"""),"07.04.2026 [V4] [WB] [LEADS-GRUPO-WHATS] 01") -> 07.04.2026 [V4] [WB] [LEADS-GRUPO-WHATS] 01 | K15: =LEFT(A15,10) -> 2026-04-11 | L15: =DATE(YEAR(SUBSTITUTE(SUBSTITUTE(K15,"-","/",1),"-","/",1)),MONTH(SUBSTITUTE(SUBSTITUTE(K15,"-","/",1),"-","/",1)),DAY(SUBSTITUTE(SUBSTITUTE(K15,"-","/",1),"-","/",1))) -> 46123 | M15: =RIGHT(C15,8) -> 81773711 | N15: =IFERROR(IF(VLOOKUP(M15,'Leads no grupo Saibai'!C:C,1,FALSE)=M15,"Sim"),"Não") -> Sim
A16: 2026-04-11T09:27:25.914Z | B16: Liliane Townsend | C16: 11984977222 | D16: lilianetownsend@hotmail.com | E16: https://lp.saibai.com.br/?utm_source=MetaAds&utm_medium=ADV+-+%5BIG%5D+%5BFB%5D+%5B30%2B%5D+%5BPIEDADE+-+40KM%5D+V%C3%81RIOS&utm_campaign=07.04.2026+%5BV4%5D+%5BWB%5D+%5BLEADS-GRUPO-WHATS%5D+01&utm_content=07.04+%5BIMG%5D+%5BAD04%5D+Pedidos+abertos&utm_term=Instagram_Reels&utm_id=120247452154580155&fbclid=PAZXh0bgNhZW0BMABhZGlkAas0bAfOj7tzcnRjBmFwcF9pZA81NjcwNjczNDMzNTI0MjcAAaely2c8bf5Z1R_xzdtshf9I8Pq7qlA2qC2r8-21ATM-5N_cyYY8dpWvnlwK_A_aem_o7S8fWG0vDPWXqUokMjr4w&campaign_id=120247452154580155&ad_id=120247452938090155 | F16: =IFERROR(__xludf.DUMMYFUNCTION("""COMPUTED_VALUE"""),"MetaAds") -> MetaAds | G16: =IFERROR(__xludf.DUMMYFUNCTION("""COMPUTED_VALUE"""),"ADV - [IG] [FB] [30%2B] [PIEDADE - 40KM] V%C3%81RIOS") -> ADV - [IG] [FB] [30%2B] [PIEDADE - 40KM] V%C3%81RIOS | H16: =IFERROR(__xludf.DUMMYFUNCTION("""COMPUTED_VALUE"""),"Instagram_Reels") -> Instagram_Reels | I16: =IFERROR(__xludf.DUMMYFUNCTION("""COMPUTED_VALUE"""),"07.04 [IMG] [AD04] Pedidos abertos") -> 07.04 [IMG] [AD04] Pedidos abertos | J16: =IFERROR(__xludf.DUMMYFUNCTION("""COMPUTED_VALUE"""),"07.04.2026 [V4] [WB] [LEADS-GRUPO-WHATS] 01") -> 07.04.2026 [V4] [WB] [LEADS-GRUPO-WHATS] 01 | K16: =LEFT(A16,10) -> 2026-04-11 | L16: =DATE(YEAR(SUBSTITUTE(SUBSTITUTE(K16,"-","/",1),"-","/",1)),MONTH(SUBSTITUTE(SUBSTITUTE(K16,"-","/",1),"-","/",1)),DAY(SUBSTITUTE(SUBSTITUTE(K16,"-","/",1),"-","/",1))) -> 46123 | M16: =RIGHT(C16,8) -> 84977222 | N16: =IFERROR(IF(VLOOKUP(M16,'Leads no grupo Saibai'!C:C,1,FALSE)=M16,"Sim"),"Não") -> Sim
A17: 2026-04-11T09:39:23.742Z | B17: Charles Propheta | C17: 55159914599 | D17: lifepraca@gmail.com | E17: https://lp.saibai.com.br/?utm_source=MetaAds&utm_medium=ADV+-+%5BIG%5D+%5BFB%5D+%5B30%2B%5D+%5BPIEDADE+-+40KM%5D+V%C3%81RIOS&utm_campaign=07.04.2026+%5BV4%5D+%5BWB%5D+%5BLEADS-GRUPO-WHATS%5D+01&utm_content=07.04+%5BIMG%5D+%5BAD04%5D+Pedidos+abertos&utm_term=Facebook_Mobile_Feed&fbclid=IwZXh0bgNhZW0BMABhZGlkAas0bAW7ZytzcnRjBmFwcF9pZAwzNTA2ODU1MzE3MjgAAR5fMltPma27TiBvPk6GOBmzcvTbpVrbgAyqNnJOPolpeNUYS08HvvZYGf02Ng_aem_ANy7GA0S2VMWVJgxFfb-Mg&campaign_id=120247452154580155&ad_id=120247452938090155&utm_id=120247452154580155 | F17: =IFERROR(__xludf.DUMMYFUNCTION("""COMPUTED_VALUE"""),"MetaAds") -> MetaAds | G17: =IFERROR(__xludf.DUMMYFUNCTION("""COMPUTED_VALUE"""),"ADV - [IG] [FB] [30%2B] [PIEDADE - 40KM] V%C3%81RIOS") -> ADV - [IG] [FB] [30%2B] [PIEDADE - 40KM] V%C3%81RIOS | H17: =IFERROR(__xludf.DUMMYFUNCTION("""COMPUTED_VALUE"""),"Facebook_Mobile_Feed") -> Facebook_Mobile_Feed | I17: =IFERROR(__xludf.DUMMYFUNCTION("""COMPUTED_VALUE"""),"07.04 [IMG] [AD04] Pedidos abertos") -> 07.04 [IMG] [AD04] Pedidos abertos | J17: =IFERROR(__xludf.DUMMYFUNCTION("""COMPUTED_VALUE"""),"07.04.2026 [V4] [WB] [LEADS-GRUPO-WHATS] 01") -> 07.04.2026 [V4] [WB] [LEADS-GRUPO-WHATS] 01 | K17: =LEFT(A17,10) -> 2026-04-11 | L17: =DATE(YEAR(SUBSTITUTE(SUBSTITUTE(K17,"-","/",1),"-","/",1)),MONTH(SUBSTITUTE(SUBSTITUTE(K17,"-","/",1),"-","/",1)),DAY(SUBSTITUTE(SUBSTITUTE(K17,"-","/",1),"-","/",1))) -> 46123 | M17: =RIGHT(C17,8) -> 59914599 | N17: =IFERROR(IF(VLOOKUP(M17,'Leads no grupo Saibai'!C:C,1,FALSE)=M17,"Sim"),"Não") -> Não
A18: 2026-04-11T09:46:38.100Z | B18: Maira Gatto | C18: 55159912266 | D18: maira.gatto@hotmail.com | E18: https://lp.saibai.com.br/?utm_source=MetaAds&utm_medium=ADV+-+%5BIG%5D+%5BFB%5D+%5B30%2B%5D+%5BPIEDADE+-+40KM%5D+V%C3%81RIOS&utm_campaign=07.04.2026+%5BV4%5D+%5BWB%5D+%5BLEADS-GRUPO-WHATS%5D+01&utm_content=07.04+%5BIMG%5D+%5BAD04%5D+Pedidos+abertos&utm_term=Facebook_Mobile_Feed&fbclid=IwZXh0bgNhZW0BMABhZGlkAas0bAW7ZytzcnRjBmFwcF9pZAwzNTA2ODU1MzE3MjgAAR5Jqo986l2Sci96yOA4olFRL2HBhKuV40DXg7FUazU3UTpbOVoVyCSjXwRfGA_aem_B667vrz-6KHgh2qBxOzaYg&campaign_id=120247452154580155&ad_id=120247452938090155&utm_id=120247452154580155 | F18: =IFERROR(__xludf.DUMMYFUNCTION("""COMPUTED_VALUE"""),"MetaAds") -> MetaAds | G18: =IFERROR(__xludf.DUMMYFUNCTION("""COMPUTED_VALUE"""),"ADV - [IG] [FB] [30%2B] [PIEDADE - 40KM] V%C3%81RIOS") -> ADV - [IG] [FB] [30%2B] [PIEDADE - 40KM] V%C3%81RIOS | H18: =IFERROR(__xludf.DUMMYFUNCTION("""COMPUTED_VALUE"""),"Facebook_Mobile_Feed") -> Facebook_Mobile_Feed | I18: =IFERROR(__xludf.DUMMYFUNCTION("""COMPUTED_VALUE"""),"07.04 [IMG] [AD04] Pedidos abertos") -> 07.04 [IMG] [AD04] Pedidos abertos | J18: =IFERROR(__xludf.DUMMYFUNCTION("""COMPUTED_VALUE"""),"07.04.2026 [V4] [WB] [LEADS-GRUPO-WHATS] 01") -> 07.04.2026 [V4] [WB] [LEADS-GRUPO-WHATS] 01 | K18: =LEFT(A18,10) -> 2026-04-11 | L18: =DATE(YEAR(SUBSTITUTE(SUBSTITUTE(K18,"-","/",1),"-","/",1)),MONTH(SUBSTITUTE(SUBSTITUTE(K18,"-","/",1),"-","/",1)),DAY(SUBSTITUTE(SUBSTITUTE(K18,"-","/",1),"-","/",1))) -> 46123 | M18: =RIGHT(C18,8) -> 59912266 | N18: =IFERROR(IF(VLOOKUP(M18,'Leads no grupo Saibai'!C:C,1,FALSE)=M18,"Sim"),"Não") -> Não
A19: 2026-04-11T10:16:55.353Z | B19: Gilberto Cardoso | C19: 11974751568 | D19: gilbertocardosovie@yahoo.com.br | E19: https://lp.saibai.com.br/?utm_source=MetaAds&utm_medium=ADV+-+%5BIG%5D+%5BFB%5D+%5B30%2B%5D+%5BPIEDADE+-+40KM%5D+V%C3%81RIOS&utm_campaign=07.04.2026+%5BV4%5D+%5BWB%5D+%5BLEADS-GRUPO-WHATS%5D+02&utm_content=07.04+%5BIMG%5D+%5BAD04%5D+Pedidos+abertos&utm_term=Instagram_Stories&utm_id=120248254459350155&fbclid=PAZXh0bgNhZW0BMABhZGlkAas1g0M2JftzcnRjBmFwcF9pZA81NjcwNjczNDMzNTI0MjcAAae-Pi9C5ulqTw1avKSlCfTlAiaFlEjDorhtO4cBmGvSCiUKaU-KCcm7ipMffA_aem_qVPH0fA8b5aEFs-o7UHCZA&campaign_id=120248254459350155&ad_id=120248254459370155 | F19: =IFERROR(__xludf.DUMMYFUNCTION("""COMPUTED_VALUE"""),"MetaAds") -> MetaAds | G19: =IFERROR(__xludf.DUMMYFUNCTION("""COMPUTED_VALUE"""),"ADV - [IG] [FB] [30%2B] [PIEDADE - 40KM] V%C3%81RIOS") -> ADV - [IG] [FB] [30%2B] [PIEDADE - 40KM] V%C3%81RIOS | H19: =IFERROR(__xludf.DUMMYFUNCTION("""COMPUTED_VALUE"""),"Instagram_Stories") -> Instagram_Stories | I19: =IFERROR(__xludf.DUMMYFUNCTION("""COMPUTED_VALUE"""),"07.04 [IMG] [AD04] Pedidos abertos") -> 07.04 [IMG] [AD04] Pedidos abertos | J19: =IFERROR(__xludf.DUMMYFUNCTION("""COMPUTED_VALUE"""),"07.04.2026 [V4] [WB] [LEADS-GRUPO-WHATS] 02") -> 07.04.2026 [V4] [WB] [LEADS-GRUPO-WHATS] 02 | K19: =LEFT(A19,10) -> 2026-04-11 | L19: =DATE(YEAR(SUBSTITUTE(SUBSTITUTE(K19,"-","/",1),"-","/",1)),MONTH(SUBSTITUTE(SUBSTITUTE(K19,"-","/",1),"-","/",1)),DAY(SUBSTITUTE(SUBSTITUTE(K19,"-","/",1),"-","/",1))) -> 46123 | M19: =RIGHT(C19,8) -> 74751568 | N19: =IFERROR(IF(VLOOKUP(M19,'Leads no grupo Saibai'!C:C,1,FALSE)=M19,"Sim"),"Não") -> Sim
A20: 2026-04-11T10:53:19.291Z | B20: Solange da | C20: 15991039369 | D20: sc_marcolini@hotmail.com | E20: https://lp.saibai.com.br/?utm_source=MetaAds&utm_medium=ADV+-+%5BIG%5D+%5BFB%5D+%5B30%2B%5D+%5BPIEDADE+-+40KM%5D+V%C3%81RIOS&utm_campaign=07.04.2026+%5BV4%5D+%5BWB%5D+%5BLEADS-GRUPO-WHATS%5D+01&utm_content=07.04+%5BIMG%5D+%5BAD04%5D+Pedidos+abertos&utm_term=Facebook_Mobile_Reels&fbclid=IwZXh0bgNhZW0BMABhZGlkAas0bAW7ZytzcnRjBmFwcF9pZAwzNTA2ODU1MzE3MjgAAR7EuNGZkOXTRnrvcdFCcgaWIYD3wGDG7rRAAY71NSXZ2Pl_gqg3REC83fAwpA_aem_pnNhTBJcvTiYaZe86OJQgA&campaign_id=120247452154580155&ad_id=120247452938090155&utm_id=120247452154580155 | F20: =IFERROR(__xludf.DUMMYFUNCTION("""COMPUTED_VALUE"""),"MetaAds") -> MetaAds | G20: =IFERROR(__xludf.DUMMYFUNCTION("""COMPUTED_VALUE"""),"ADV - [IG] [FB] [30%2B] [PIEDADE - 40KM] V%C3%81RIOS") -> ADV - [IG] [FB] [30%2B] [PIEDADE - 40KM] V%C3%81RIOS | H20: =IFERROR(__xludf.DUMMYFUNCTION("""COMPUTED_VALUE"""),"Facebook_Mobile_Reels") -> Facebook_Mobile_Reels | I20: =IFERROR(__xludf.DUMMYFUNCTION("""COMPUTED_VALUE"""),"07.04 [IMG] [AD04] Pedidos abertos") -> 07.04 [IMG] [AD04] Pedidos abertos | J20: =IFERROR(__xludf.DUMMYFUNCTION("""COMPUTED_VALUE"""),"07.04.2026 [V4] [WB] [LEADS-GRUPO-WHATS] 01") -> 07.04.2026 [V4] [WB] [LEADS-GRUPO-WHATS] 01 | K20: =LEFT(A20,10) -> 2026-04-11 | L20: =DATE(YEAR(SUBSTITUTE(SUBSTITUTE(K20,"-","/",1),"-","/",1)),MONTH(SUBSTITUTE(SUBSTITUTE(K20,"-","/",1),"-","/",1)),DAY(SUBSTITUTE(SUBSTITUTE(K20,"-","/",1),"-","/",1))) -> 46123 | M20: =RIGHT(C20,8) -> 91039369 | N20: =IFERROR(IF(VLOOKUP(M20,'Leads no grupo Saibai'!C:C,1,FALSE)=M20,"Sim"),"Não") -> Não
A21: 2026-04-11T13:22:18.922Z | B21: Alessandra Augusto Costa | C21: 15996313568 | D21: aaugustocosta@prof.educacao.sp.gov.br | E21: https://lp.saibai.com.br/?utm_source=MetaAds&utm_medium=ADV+-+%5BIG%5D+%5BFB%5D+%5B30%2B%5D+%5BPIEDADE+-+40KM%5D+V%C3%81RIOS&utm_campaign=07.04.2026+%5BV4%5D+%5BWB%5D+%5BLEADS-GRUPO-WHATS%5D+02&utm_content=07.04+%5BIMG%5D+%5BAD04%5D+Pedidos+abertos&utm_term=Instagram_Stories&utm_id=120248254459350155&fbclid=PAZXh0bgNhZW0BMABhZGlkAas1g0M2JftzcnRjBmFwcF9pZA81NjcwNjczNDMzNTI0MjcAAae-Pi9C5ulqTw1avKSlCfTlAiaFlEjDorhtO4cBmGvSCiUKaU-KCcm7ipMffA_aem_qVPH0fA8b5aEFs-o7UHCZA&campaign_id=120248254459350155&ad_id=120248254459370155 | F21: =IFERROR(__xludf.DUMMYFUNCTION("""COMPUTED_VALUE"""),"MetaAds") -> MetaAds | G21: =IFERROR(__xludf.DUMMYFUNCTION("""COMPUTED_VALUE"""),"ADV - [IG] [FB] [30%2B] [PIEDADE - 40KM] V%C3%81RIOS") -> ADV - [IG] [FB] [30%2B] [PIEDADE - 40KM] V%C3%81RIOS | H21: =IFERROR(__xludf.DUMMYFUNCTION("""COMPUTED_VALUE"""),"Instagram_Stories") -> Instagram_Stories | I21: =IFERROR(__xludf.DUMMYFUNCTION("""COMPUTED_VALUE"""),"07.04 [IMG] [AD04] Pedidos abertos") -> 07.04 [IMG] [AD04] Pedidos abertos | J21: =IFERROR(__xludf.DUMMYFUNCTION("""COMPUTED_VALUE"""),"07.04.2026 [V4] [WB] [LEADS-GRUPO-WHATS] 02") -> 07.04.2026 [V4] [WB] [LEADS-GRUPO-WHATS] 02 | K21: =LEFT(A21,10) -> 2026-04-11 | L21: =DATE(YEAR(SUBSTITUTE(SUBSTITUTE(K21,"-","/",1),"-","/",1)),MONTH(SUBSTITUTE(SUBSTITUTE(K21,"-","/",1),"-","/",1)),DAY(SUBSTITUTE(SUBSTITUTE(K21,"-","/",1),"-","/",1))) -> 46123 | M21: =RIGHT(C21,8) -> 96313568 | N21: =IFERROR(IF(VLOOKUP(M21,'Leads no grupo Saibai'!C:C,1,FALSE)=M21,"Sim"),"Não") -> Sim
A22: 2026-04-11T14:20:39.848Z | B22: Aparecida | C22: 15996291515 | D22: cidazanela@hotmail.com | E22: https://lp.saibai.com.br/?utm_source=MetaAds&utm_medium=ADV+-+%5BIG%5D+%5BFB%5D+%5B30%2B%5D+%5BPIEDADE+-+40KM%5D+V%C3%81RIOS&utm_campaign=07.04.2026+%5BV4%5D+%5BWB%5D+%5BLEADS-GRUPO-WHATS%5D+01&utm_content=07.04+%5BIMG%5D+%5BAD04%5D+Pedidos+abertos&utm_term=Facebook_Mobile_Feed&fbclid=IwZXh0bgNhZW0BMABhZGlkAas0bAW7ZytzcnRjBmFwcF9pZAwzNTA2ODU1MzE3MjgAAR4CvRkqhDILzZPGlshiEbcAOWFjQj5UjRNL9-ML4APpZkL2U8r77NRAz2H0RQ_aem_sbI6x_6Q467Ds4gt-qqvXQ&campaign_id=120247452154580155&ad_id=120247452938090155&utm_id=120247452154580155 | F22: =IFERROR(__xludf.DUMMYFUNCTION("""COMPUTED_VALUE"""),"MetaAds") -> MetaAds | G22: =IFERROR(__xludf.DUMMYFUNCTION("""COMPUTED_VALUE"""),"ADV - [IG] [FB] [30%2B] [PIEDADE - 40KM] V%C3%81RIOS") -> ADV - [IG] [FB] [30%2B] [PIEDADE - 40KM] V%C3%81RIOS | H22: =IFERROR(__xludf.DUMMYFUNCTION("""COMPUTED_VALUE"""),"Facebook_Mobile_Feed") -> Facebook_Mobile_Feed | I22: =IFERROR(__xludf.DUMMYFUNCTION("""COMPUTED_VALUE"""),"07.04 [IMG] [AD04] Pedidos abertos") -> 07.04 [IMG] [AD04] Pedidos abertos | J22: =IFERROR(__xludf.DUMMYFUNCTION("""COMPUTED_VALUE"""),"07.04.2026 [V4] [WB] [LEADS-GRUPO-WHATS] 01") -> 07.04.2026 [V4] [WB] [LEADS-GRUPO-WHATS] 01 | K22: =LEFT(A22,10) -> 2026-04-11 | L22: =DATE(YEAR(SUBSTITUTE(SUBSTITUTE(K22,"-","/",1),"-","/",1)),MONTH(SUBSTITUTE(SUBSTITUTE(K22,"-","/",1),"-","/",1)),DAY(SUBSTITUTE(SUBSTITUTE(K22,"-","/",1),"-","/",1))) -> 46123 | M22: =RIGHT(C22,8) -> 96291515 | N22: =IFERROR(IF(VLOOKUP(M22,'Leads no grupo Saibai'!C:C,1,FALSE)=M22,"Sim"),"Não") -> Não
A23: 2026-04-11T14:43:42.537Z | B23: edmaradeoliveira44@gmail.com | C23: 15996667904 | D23: edmaradeoliveira44@gmail.co.com | E23: https://lp.saibai.com.br/?utm_source=MetaAds&utm_medium=ADV+-+%5BIG%5D+%5BFB%5D+%5B30%2B%5D+%5BPIEDADE+-+40KM%5D+V%C3%81RIOS&utm_campaign=07.04.2026+%5BV4%5D+%5BWB%5D+%5BLEADS-GRUPO-WHATS%5D+01&utm_content=07.04+%5BIMG%5D+%5BAD04%5D+Pedidos+abertos&utm_term=Instagram_Feed&utm_id=120247452154580155&fbclid=PAZXh0bgNhZW0BMABhZGlkAas0bAW7ZytzcnRjBmFwcF9pZA81NjcwNjczNDMzNTI0MjcAAaf2PMnI02jF2DvJxBzra9hp8TYq2K4AR3kKRePi_cY_5YRyduph0lZXi5-i9A_aem_YZ9lMCmM6-MXXAoRyV5nbw&campaign_id=120247452154580155&ad_id=120247452938090155 | F23: =IFERROR(__xludf.DUMMYFUNCTION("""COMPUTED_VALUE"""),"MetaAds") -> MetaAds | G23: =IFERROR(__xludf.DUMMYFUNCTION("""COMPUTED_VALUE"""),"ADV - [IG] [FB] [30%2B] [PIEDADE - 40KM] V%C3%81RIOS") -> ADV - [IG] [FB] [30%2B] [PIEDADE - 40KM] V%C3%81RIOS | H23: =IFERROR(__xludf.DUMMYFUNCTION("""COMPUTED_VALUE"""),"Instagram_Feed") -> Instagram_Feed | I23: =IFERROR(__xludf.DUMMYFUNCTION("""COMPUTED_VALUE"""),"07.04 [IMG] [AD04] Pedidos abertos") -> 07.04 [IMG] [AD04] Pedidos abertos | J23: =IFERROR(__xludf.DUMMYFUNCTION("""COMPUTED_VALUE"""),"07.04.2026 [V4] [WB] [LEADS-GRUPO-WHATS] 01") -> 07.04.2026 [V4] [WB] [LEADS-GRUPO-WHATS] 01 | K23: =LEFT(A23,10) -> 2026-04-11 | L23: =DATE(YEAR(SUBSTITUTE(SUBSTITUTE(K23,"-","/",1),"-","/",1)),MONTH(SUBSTITUTE(SUBSTITUTE(K23,"-","/",1),"-","/",1)),DAY(SUBSTITUTE(SUBSTITUTE(K23,"-","/",1),"-","/",1))) -> 46123 | M23: =RIGHT(C23,8) -> 96667904 | N23: =IFERROR(IF(VLOOKUP(M23,'Leads no grupo Saibai'!C:C,1,FALSE)=M23,"Sim"),"Não") -> Sim
A24: 2026-04-11T16:10:54.439Z | B24: Lenice Santos | C24: 15997321884 | D24: lenice.ap.santos@gmail.com | E24: https://lp.saibai.com.br/?utm_source=MetaAds&utm_medium=ADV+-+%5BIG%5D+%5BFB%5D+%5B30%2B%5D+%5BPIEDADE+-+40KM%5D+V%C3%81RIOS&utm_campaign=07.04.2026+%5BV4%5D+%5BWB%5D+%5BLEADS-GRUPO-WHATS%5D+01&utm_content=07.04+%5BIMG%5D+%5BAD04%5D+Pedidos+abertos&utm_term=Facebook_Mobile_Feed&fbclid=IwZXh0bgNhZW0BMABhZGlkAas0bAfOj7tzcnRjBmFwcF9pZAwzNTA2ODU1MzE3MjgAAR4o0x0VZm88HbTlzU_bZzH_d-IXUDKHJV8aNjcrYdEI1jZl0xS7IFYIdOjuTA_aem_GdnH90_FI7_irV8br8itIA&campaign_id=120247452154580155&ad_id=120247452938090155&utm_id=120247452154580155 | F24: =IFERROR(__xludf.DUMMYFUNCTION("""COMPUTED_VALUE"""),"MetaAds") -> MetaAds | G24: =IFERROR(__xludf.DUMMYFUNCTION("""COMPUTED_VALUE"""),"ADV - [IG] [FB] [30%2B] [PIEDADE - 40KM] V%C3%81RIOS") -> ADV - [IG] [FB] [30%2B] [PIEDADE - 40KM] V%C3%81RIOS | H24: =IFERROR(__xludf.DUMMYFUNCTION("""COMPUTED_VALUE"""),"Facebook_Mobile_Feed") -> Facebook_Mobile_Feed | I24: =IFERROR(__xludf.DUMMYFUNCTION("""COMPUTED_VALUE"""),"07.04 [IMG] [AD04] Pedidos abertos") -> 07.04 [IMG] [AD04] Pedidos abertos | J24: =IFERROR(__xludf.DUMMYFUNCTION("""COMPUTED_VALUE"""),"07.04.2026 [V4] [WB] [LEADS-GRUPO-WHATS] 01") -> 07.04.2026 [V4] [WB] [LEADS-GRUPO-WHATS] 01 | K24: =LEFT(A24,10) -> 2026-04-11 | L24: =DATE(YEAR(SUBSTITUTE(SUBSTITUTE(K24,"-","/",1),"-","/",1)),MONTH(SUBSTITUTE(SUBSTITUTE(K24,"-","/",1),"-","/",1)),DAY(SUBSTITUTE(SUBSTITUTE(K24,"-","/",1),"-","/",1))) -> 46123 | M24: =RIGHT(C24,8) -> 97321884 | N24: =IFERROR(IF(VLOOKUP(M24,'Leads no grupo Saibai'!C:C,1,FALSE)=M24,"Sim"),"Não") -> Não
A25: 2026-04-11T19:35:01.479Z | B25: Maisa Torres | C25: 15991143109 | D25: maisapxo@yahoo.com.br | E25: https://lp.saibai.com.br/?utm_source=MetaAds&utm_medium=ADV+-+%5BIG%5D+%5BFB%5D+%5B30%2B%5D+%5BPIEDADE+-+40KM%5D+V%C3%81RIOS&utm_campaign=07.04.2026+%5BV4%5D+%5BWB%5D+%5BLEADS-GRUPO-WHATS%5D+01&utm_content=07.04+%5BIMG%5D+%5BAD04%5D+Pedidos+abertos&utm_term=Instagram_Stories&utm_id=120247452154580155&fbclid=PAZXh0bgNhZW0BMABhZGlkAas0a_lii3tzcnRjBmFwcF9pZA81NjcwNjczNDMzNTI0MjcAAae-K-ywuFXkHPpcn5lIWZjVpFnHSAliaUgsyVFu7MPBd7NtGWxucH_zdNs26g_aem_V8pnN_tD-7Sd8qyolMoDew&campaign_id=120247452154580155&ad_id=120247452938090155 | F25: =IFERROR(__xludf.DUMMYFUNCTION("""COMPUTED_VALUE"""),"MetaAds") -> MetaAds | G25: =IFERROR(__xludf.DUMMYFUNCTION("""COMPUTED_VALUE"""),"ADV - [IG] [FB] [30%2B] [PIEDADE - 40KM] V%C3%81RIOS") -> ADV - [IG] [FB] [30%2B] [PIEDADE - 40KM] V%C3%81RIOS | H25: =IFERROR(__xludf.DUMMYFUNCTION("""COMPUTED_VALUE"""),"Instagram_Stories") -> Instagram_Stories | I25: =IFERROR(__xludf.DUMMYFUNCTION("""COMPUTED_VALUE"""),"07.04 [IMG] [AD04] Pedidos abertos") -> 07.04 [IMG] [AD04] Pedidos abertos | J25: =IFERROR(__xludf.DUMMYFUNCTION("""COMPUTED_VALUE"""),"07.04.2026 [V4] [WB] [LEADS-GRUPO-WHATS] 01") -> 07.04.2026 [V4] [WB] [LEADS-GRUPO-WHATS] 01 | K25: =LEFT(A25,10) -> 2026-04-11 | L25: =DATE(YEAR(SUBSTITUTE(SUBSTITUTE(K25,"-","/",1),"-","/",1)),MONTH(SUBSTITUTE(SUBSTITUTE(K25,"-","/",1),"-","/",1)),DAY(SUBSTITUTE(SUBSTITUTE(K25,"-","/",1),"-","/",1))) -> 46123 | M25: =RIGHT(C25,8) -> 91143109 | N25: =IFERROR(IF(VLOOKUP(M25,'Leads no grupo Saibai'!C:C,1,FALSE)=M25,"Sim"),"Não") -> Sim
A26: 2026-04-11T20:58:48.045Z | B26: Suely A foschi tomazoli | C26: 11917539658 | D26: sufoschi@hotmail.com | E26: https://lp.saibai.com.br/?utm_source=MetaAds&utm_medium=ADV+-+%5BIG%5D+%5BFB%5D+%5B30%2B%5D+%5BPIEDADE+-+40KM%5D+V%C3%81RIOS&utm_campaign=07.04.2026+%5BV4%5D+%5BWB%5D+%5BLEADS-GRUPO-WHATS%5D+01&utm_content=07.04+%5BIMG%5D+%5BAD04%5D+Pedidos+abertos&utm_term=Instagram_Stories&utm_id=120247452154580155&fbclid=PAZXh0bgNhZW0BMABhZGlkAas0bAW7ZytzcnRjBmFwcF9pZA81NjcwNjczNDMzNTI0MjcAAadAxH3LT6FELi8bDGwd1vAmuhZ0tpf_dxifFPpTLpahm2EHVGei94hN4-wA8Q_aem_umlTAOYv8wHa8qH-QrvxkA&campaign_id=120247452154580155&ad_id=120247452938090155 | F26: =IFERROR(__xludf.DUMMYFUNCTION("""COMPUTED_VALUE"""),"MetaAds") -> MetaAds | G26: =IFERROR(__xludf.DUMMYFUNCTION("""COMPUTED_VALUE"""),"ADV - [IG] [FB] [30%2B] [PIEDADE - 40KM] V%C3%81RIOS") -> ADV - [IG] [FB] [30%2B] [PIEDADE - 40KM] V%C3%81RIOS | H26: =IFERROR(__xludf.DUMMYFUNCTION("""COMPUTED_VALUE"""),"Instagram_Stories") -> Instagram_Stories | I26: =IFERROR(__xludf.DUMMYFUNCTION("""COMPUTED_VALUE"""),"07.04 [IMG] [AD04] Pedidos abertos") -> 07.04 [IMG] [AD04] Pedidos abertos | J26: =IFERROR(__xludf.DUMMYFUNCTION("""COMPUTED_VALUE"""),"07.04.2026 [V4] [WB] [LEADS-GRUPO-WHATS] 01") -> 07.04.2026 [V4] [WB] [LEADS-GRUPO-WHATS] 01 | K26: =LEFT(A26,10) -> 2026-04-11 | L26: =DATE(YEAR(SUBSTITUTE(SUBSTITUTE(K26,"-","/",1),"-","/",1)),MONTH(SUBSTITUTE(SUBSTITUTE(K26,"-","/",1),"-","/",1)),DAY(SUBSTITUTE(SUBSTITUTE(K26,"-","/",1),"-","/",1))) -> 46123 | M26: =RIGHT(C26,8) -> 17539658 | N26: =IFERROR(IF(VLOOKUP(M26,'Leads no grupo Saibai'!C:C,1,FALSE)=M26,"Sim"),"Não") -> Sim
A27: 2026-04-12T03:09:06.634Z | B27: Kelly Hollen | C27: 15988211837 | D27: damaris.hollen@gmail.com | E27: https://lp.saibai.com.br/?utm_source=MetaAds&utm_medium=ADV+-+%5BIG%5D+%5BFB%5D+%5B30%2B%5D+%5BPIEDADE+-+40KM%5D+V%C3%81RIOS&utm_campaign=07.04.2026+%5BV4%5D+%5BWB%5D+%5BLEADS-GRUPO-WHATS%5D+01&utm_content=07.04+%5BIMG%5D+%5BAD04%5D+Pedidos+abertos&utm_term=Facebook_Mobile_Feed&fbclid=IwZXh0bgNhZW0BMABhZGlkAas0bAW7ZytzcnRjBmFwcF9pZAwzNTA2ODU1MzE3MjgAAR7w8SeqRb8h8EvmPYCA7gNfTn1K-lKEeGUPkD0_ZBStGWUp2RrqZ_T6RaEz9g_aem_nCmRvMh7BrM-_rsWkPmvmQ&campaign_id=120247452154580155&ad_id=120247452938090155&utm_id=120247452154580155 | F27: =IFERROR(__xludf.DUMMYFUNCTION("""COMPUTED_VALUE"""),"MetaAds") -> MetaAds | G27: =IFERROR(__xludf.DUMMYFUNCTION("""COMPUTED_VALUE"""),"ADV - [IG] [FB] [30%2B] [PIEDADE - 40KM] V%C3%81RIOS") -> ADV - [IG] [FB] [30%2B] [PIEDADE - 40KM] V%C3%81RIOS | H27: =IFERROR(__xludf.DUMMYFUNCTION("""COMPUTED_VALUE"""),"Facebook_Mobile_Feed") -> Facebook_Mobile_Feed | I27: =IFERROR(__xludf.DUMMYFUNCTION("""COMPUTED_VALUE"""),"07.04 [IMG] [AD04] Pedidos abertos") -> 07.04 [IMG] [AD04] Pedidos abertos | J27: =IFERROR(__xludf.DUMMYFUNCTION("""COMPUTED_VALUE"""),"07.04.2026 [V4] [WB] [LEADS-GRUPO-WHATS] 01") -> 07.04.2026 [V4] [WB] [LEADS-GRUPO-WHATS] 01 | K27: =LEFT(A27,10) -> 2026-04-12 | L27: =DATE(YEAR(SUBSTITUTE(SUBSTITUTE(K27,"-","/",1),"-","/",1)),MONTH(SUBSTITUTE(SUBSTITUTE(K27,"-","/",1),"-","/",1)),DAY(SUBSTITUTE(SUBSTITUTE(K27,"-","/",1),"-","/",1))) -> 46124 | M27: =RIGHT(C27,8) -> 88211837 | N27: =IFERROR(IF(VLOOKUP(M27,'Leads no grupo Saibai'!C:C,1,FALSE)=M27,"Sim"),"Não") -> Sim
A28: 2026-04-12T03:39:29.364Z | B28: Girlane Sousa | C28: 15988030611 | D28: girlanesouza2014@gmail.com | E28: https://lp.saibai.com.br/?utm_source=MetaAds&utm_medium=ADV+-+%5BIG%5D+%5BFB%5D+%5B30%2B%5D+%5BPIEDADE+-+40KM%5D+V%C3%81RIOS&utm_campaign=07.04.2026+%5BV4%5D+%5BWB%5D+%5BLEADS-GRUPO-WHATS%5D+01&utm_content=07.04+%5BIMG%5D+%5BAD04%5D+Pedidos+abertos&utm_term=Facebook_Mobile_Feed&fbclid=IwZXh0bgNhZW0BMABhZGlkAas0bAW7ZytzcnRjBmFwcF9pZAwzNTA2ODU1MzE3MjgAAR6v67-LuhXYM-RpYXTVFX4MMcZjvWW79d5VE5p-VmkBuPiWFbuD2AyYE1E9Xg_aem_fkRBUDx8LS4EAP6T7hYglA&campaign_id=120247452154580155&ad_id=120247452938090155&utm_id=120247452154580155 | F28: =IFERROR(__xludf.DUMMYFUNCTION("""COMPUTED_VALUE"""),"MetaAds") -> MetaAds | G28: =IFERROR(__xludf.DUMMYFUNCTION("""COMPUTED_VALUE"""),"ADV - [IG] [FB] [30%2B] [PIEDADE - 40KM] V%C3%81RIOS") -> ADV - [IG] [FB] [30%2B] [PIEDADE - 40KM] V%C3%81RIOS | H28: =IFERROR(__xludf.DUMMYFUNCTION("""COMPUTED_VALUE"""),"Facebook_Mobile_Feed") -> Facebook_Mobile_Feed | I28: =IFERROR(__xludf.DUMMYFUNCTION("""COMPUTED_VALUE"""),"07.04 [IMG] [AD04] Pedidos abertos") -> 07.04 [IMG] [AD04] Pedidos abertos | J28: =IFERROR(__xludf.DUMMYFUNCTION("""COMPUTED_VALUE"""),"07.04.2026 [V4] [WB] [LEADS-GRUPO-WHATS] 01") -> 07.04.2026 [V4] [WB] [LEADS-GRUPO-WHATS] 01 | K28: =LEFT(A28,10) -> 2026-04-12 | L28: =DATE(YEAR(SUBSTITUTE(SUBSTITUTE(K28,"-","/",1),"-","/",1)),MONTH(SUBSTITUTE(SUBSTITUTE(K28,"-","/",1),"-","/",1)),DAY(SUBSTITUTE(SUBSTITUTE(K28,"-","/",1),"-","/",1))) -> 46124 | M28: =RIGHT(C28,8) -> 88030611 | N28: =IFERROR(IF(VLOOKUP(M28,'Leads no grupo Saibai'!C:C,1,FALSE)=M28,"Sim"),"Não") -> Sim
A29: 2026-04-12T03:39:56.328Z | B29: Girlane Sousa | C29: 15988030611 | D29: girlanesouza2014@gmail.com | E29: https://lp.saibai.com.br/?utm_source=MetaAds&utm_medium=ADV+-+%5BIG%5D+%5BFB%5D+%5B30%2B%5D+%5BPIEDADE+-+40KM%5D+V%C3%81RIOS&utm_campaign=07.04.2026+%5BV4%5D+%5BWB%5D+%5BLEADS-GRUPO-WHATS%5D+01&utm_content=07.04+%5BIMG%5D+%5BAD04%5D+Pedidos+abertos&utm_term=Facebook_Mobile_Feed&fbclid=IwZXh0bgNhZW0BMABhZGlkAas0bAW7ZytzcnRjBmFwcF9pZAwzNTA2ODU1MzE3MjgAAR6v67-LuhXYM-RpYXTVFX4MMcZjvWW79d5VE5p-VmkBuPiWFbuD2AyYE1E9Xg_aem_fkRBUDx8LS4EAP6T7hYglA&campaign_id=120247452154580155&ad_id=120247452938090155&utm_id=120247452154580155 | F29: =IFERROR(__xludf.DUMMYFUNCTION("""COMPUTED_VALUE"""),"MetaAds") -> MetaAds | G29: =IFERROR(__xludf.DUMMYFUNCTION("""COMPUTED_VALUE"""),"ADV - [IG] [FB] [30%2B] [PIEDADE - 40KM] V%C3%81RIOS") -> ADV - [IG] [FB] [30%2B] [PIEDADE - 40KM] V%C3%81RIOS | H29: =IFERROR(__xludf.DUMMYFUNCTION("""COMPUTED_VALUE"""),"Facebook_Mobile_Feed") -> Facebook_Mobile_Feed | I29: =IFERROR(__xludf.DUMMYFUNCTION("""COMPUTED_VALUE"""),"07.04 [IMG] [AD04] Pedidos abertos") -> 07.04 [IMG] [AD04] Pedidos abertos | J29: =IFERROR(__xludf.DUMMYFUNCTION("""COMPUTED_VALUE"""),"07.04.2026 [V4] [WB] [LEADS-GRUPO-WHATS] 01") -> 07.04.2026 [V4] [WB] [LEADS-GRUPO-WHATS] 01 | K29: =LEFT(A29,10) -> 2026-04-12 | L29: =DATE(YEAR(SUBSTITUTE(SUBSTITUTE(K29,"-","/",1),"-","/",1)),MONTH(SUBSTITUTE(SUBSTITUTE(K29,"-","/",1),"-","/",1)),DAY(SUBSTITUTE(SUBSTITUTE(K29,"-","/",1),"-","/",1))) -> 46124 | M29: =RIGHT(C29,8) -> 88030611 | N29: =IFERROR(IF(VLOOKUP(M29,'Leads no grupo Saibai'!C:C,1,FALSE)=M29,"Sim"),"Não") -> Sim
A30: 2026-04-12T04:14:08.925Z | B30: Celso Fiszbeyn | C30: 11985843932 | D30: fiszbeyn@terra.com.br | E30: https://lp.saibai.com.br/?utm_source=MetaAds&utm_medium=ADV+-+%5BIG%5D+%5BFB%5D+%5B30%2B%5D+%5BPIEDADE+-+40KM%5D+V%C3%81RIOS&utm_campaign=07.04.2026+%5BV4%5D+%5BWB%5D+%5BLEADS-GRUPO-WHATS%5D+01&utm_content=07.04+%5BIMG%5D+%5BAD01%5D+A+safra+come%C3%A7ou&utm_term=Facebook_Mobile_Feed&fbclid=IwZXh0bgNhZW0BMABhZGlkAas0a_chJvtzcnRjBmFwcF9pZAwzNTA2ODU1MzE3MjgAAR6EcW4KwQkvPDQw168P-NKhi-OG7DUh-hlnToKUGL7g57mEjwtnHqCR0cApzg_aem_m1GgtNyhBt04gOoDEn8ZDA&campaign_id=120247452154580155&ad_id=120247452154590155&utm_id=120247452154580155 | F30: =IFERROR(__xludf.DUMMYFUNCTION("""COMPUTED_VALUE"""),"MetaAds") -> MetaAds | G30: =IFERROR(__xludf.DUMMYFUNCTION("""COMPUTED_VALUE"""),"ADV - [IG] [FB] [30%2B] [PIEDADE - 40KM] V%C3%81RIOS") -> ADV - [IG] [FB] [30%2B] [PIEDADE - 40KM] V%C3%81RIOS | H30: =IFERROR(__xludf.DUMMYFUNCTION("""COMPUTED_VALUE"""),"Facebook_Mobile_Feed") -> Facebook_Mobile_Feed | I30: =IFERROR(__xludf.DUMMYFUNCTION("""COMPUTED_VALUE"""),"07.04 [IMG] [AD01] A safra come%C3%A7ou") -> 07.04 [IMG] [AD01] A safra come%C3%A7ou | J30: =IFERROR(__xludf.DUMMYFUNCTION("""COMPUTED_VALUE"""),"07.04.2026 [V4] [WB] [LEADS-GRUPO-WHATS] 01") -> 07.04.2026 [V4] [WB] [LEADS-GRUPO-WHATS] 01 | K30: =LEFT(A30,10) -> 2026-04-12 | L30: =DATE(YEAR(SUBSTITUTE(SUBSTITUTE(K30,"-","/",1),"-","/",1)),MONTH(SUBSTITUTE(SUBSTITUTE(K30,"-","/",1),"-","/",1)),DAY(SUBSTITUTE(SUBSTITUTE(K30,"-","/",1),"-","/",1))) -> 46124 | M30: =RIGHT(C30,8) -> 85843932 | N30: =IFERROR(IF(VLOOKUP(M30,'Leads no grupo Saibai'!C:C,1,FALSE)=M30,"Sim"),"Não") -> Sim
A31: 2026-04-12T04:14:23.331Z | B31: Celso Fiszbeyn | C31: 11985843932 | D31: fiszbeyn@terra.com.br | E31: https://lp.saibai.com.br/?utm_source=MetaAds&utm_medium=ADV+-+%5BIG%5D+%5BFB%5D+%5B30%2B%5D+%5BPIEDADE+-+40KM%5D+V%C3%81RIOS&utm_campaign=07.04.2026+%5BV4%5D+%5BWB%5D+%5BLEADS-GRUPO-WHATS%5D+01&utm_content=07.04+%5BIMG%5D+%5BAD01%5D+A+safra+come%C3%A7ou&utm_term=Facebook_Mobile_Feed&fbclid=IwZXh0bgNhZW0BMABhZGlkAas0a_chJvtzcnRjBmFwcF9pZAwzNTA2ODU1MzE3MjgAAR6EcW4KwQkvPDQw168P-NKhi-OG7DUh-hlnToKUGL7g57mEjwtnHqCR0cApzg_aem_m1GgtNyhBt04gOoDEn8ZDA&campaign_id=120247452154580155&ad_id=120247452154590155&utm_id=120247452154580155 | F31: =IFERROR(__xludf.DUMMYFUNCTION("""COMPUTED_VALUE"""),"MetaAds") -> MetaAds | G31: =IFERROR(__xludf.DUMMYFUNCTION("""COMPUTED_VALUE"""),"ADV - [IG] [FB] [30%2B] [PIEDADE - 40KM] V%C3%81RIOS") -> ADV - [IG] [FB] [30%2B] [PIEDADE - 40KM] V%C3%81RIOS | H31: =IFERROR(__xludf.DUMMYFUNCTION("""COMPUTED_VALUE"""),"Facebook_Mobile_Feed") -> Facebook_Mobile_Feed | I31: =IFERROR(__xludf.DUMMYFUNCTION("""COMPUTED_VALUE"""),"07.04 [IMG] [AD01] A safra come%C3%A7ou") -> 07.04 [IMG] [AD01] A safra come%C3%A7ou | J31: =IFERROR(__xludf.DUMMYFUNCTION("""COMPUTED_VALUE"""),"07.04.2026 [V4] [WB] [LEADS-GRUPO-WHATS] 01") -> 07.04.2026 [V4] [WB] [LEADS-GRUPO-WHATS] 01 | K31: =LEFT(A31,10) -> 2026-04-12 | L31: =DATE(YEAR(SUBSTITUTE(SUBSTITUTE(K31,"-","/",1),"-","/",1)),MONTH(SUBSTITUTE(SUBSTITUTE(K31,"-","/",1),"-","/",1)),DAY(SUBSTITUTE(SUBSTITUTE(K31,"-","/",1),"-","/",1))) -> 46124 | M31: =RIGHT(C31,8) -> 85843932 | N31: =IFERROR(IF(VLOOKUP(M31,'Leads no grupo Saibai'!C:C,1,FALSE)=M31,"Sim"),"Não") -> Sim
A32: 2026-04-12T12:10:42.857Z | B32: Celso Fiszbeyn | C32: 11985843932 | D32: fiszbeyn@terra.com.br | E32: https://lp.saibai.com.br/?utm_source=MetaAds&utm_medium=ADV+-+%5BIG%5D+%5BFB%5D+%5B30%2B%5D+%5BPIEDADE+-+40KM%5D+V%C3%81RIOS&utm_campaign=07.04.2026+%5BV4%5D+%5BWB%5D+%5BLEADS-GRUPO-WHATS%5D+01&utm_content=07.04+%5BIMG%5D+%5BAD04%5D+Pedidos+abertos&utm_term=Facebook_Mobile_Feed&fbclid=IwZXh0bgNhZW0BMABhZGlkAas0bAW7ZytzcnRjBmFwcF9pZAwzNTA2ODU1MzE3MjgAAR6WOLrOPXnfYiyksmTBGYNaDAKqJ5-QSTjW0-BaeKjAR4hQeICzVlJ7CYBtgA_aem_rVGvF9I4taAyMROApCsCow&campaign_id=120247452154580155&ad_id=120247452938090155&utm_id=120247452154580155 | F32: =IFERROR(__xludf.DUMMYFUNCTION("""COMPUTED_VALUE"""),"MetaAds") -> MetaAds | G32: =IFERROR(__xludf.DUMMYFUNCTION("""COMPUTED_VALUE"""),"ADV - [IG] [FB] [30%2B] [PIEDADE - 40KM] V%C3%81RIOS") -> ADV - [IG] [FB] [30%2B] [PIEDADE - 40KM] V%C3%81RIOS | H32: =IFERROR(__xludf.DUMMYFUNCTION("""COMPUTED_VALUE"""),"Facebook_Mobile_Feed") -> Facebook_Mobile_Feed | I32: =IFERROR(__xludf.DUMMYFUNCTION("""COMPUTED_VALUE"""),"07.04 [IMG] [AD04] Pedidos abertos") -> 07.04 [IMG] [AD04] Pedidos abertos | J32: =IFERROR(__xludf.DUMMYFUNCTION("""COMPUTED_VALUE"""),"07.04.2026 [V4] [WB] [LEADS-GRUPO-WHATS] 01") -> 07.04.2026 [V4] [WB] [LEADS-GRUPO-WHATS] 01 | K32: =LEFT(A32,10) -> 2026-04-12 | L32: =DATE(YEAR(SUBSTITUTE(SUBSTITUTE(K32,"-","/",1),"-","/",1)),MONTH(SUBSTITUTE(SUBSTITUTE(K32,"-","/",1),"-","/",1)),DAY(SUBSTITUTE(SUBSTITUTE(K32,"-","/",1),"-","/",1))) -> 46124 | M32: =RIGHT(C32,8) -> 85843932 | N32: =IFERROR(IF(VLOOKUP(M32,'Leads no grupo Saibai'!C:C,1,FALSE)=M32,"Sim"),"Não") -> Sim
A33: 2026-04-12T12:20:14.074Z | B33: Renata Funchal | C33: 15981595553 | D33: renatapires.adv@gmail.com | E33: https://lp.saibai.com.br/?utm_source=MetaAds&utm_medium=ADV+-+%5BIG%5D+%5BFB%5D+%5B30%2B%5D+%5BPIEDADE+-+40KM%5D+V%C3%81RIOS&utm_campaign=07.04.2026+%5BV4%5D+%5BWB%5D+%5BLEADS-GRUPO-WHATS%5D+01&utm_content=07.04+%5BIMG%5D+%5BAD04%5D+Pedidos+abertos&utm_term=Instagram_Stories&utm_id=120247452154580155&fbclid=PAZXh0bgNhZW0BMABhZGlkAas0bAW7ZytzcnRjBmFwcF9pZA8xMjQwMjQ1NzQyODc0MTQAAado_HsUkVrToCTLgI5OWkFw_iE_k_-sbGAhzbRxE4kfpyZMIDNUC2LWe2vJsw_aem_wzs0o74Ym8t2vWSwLvHUng&campaign_id=120247452154580155&ad_id=120247452938090155 | F33: =IFERROR(__xludf.DUMMYFUNCTION("""COMPUTED_VALUE"""),"MetaAds") -> MetaAds | G33: =IFERROR(__xludf.DUMMYFUNCTION("""COMPUTED_VALUE"""),"ADV - [IG] [FB] [30%2B] [PIEDADE - 40KM] V%C3%81RIOS") -> ADV - [IG] [FB] [30%2B] [PIEDADE - 40KM] V%C3%81RIOS | H33: =IFERROR(__xludf.DUMMYFUNCTION("""COMPUTED_VALUE"""),"Instagram_Stories") -> Instagram_Stories | I33: =IFERROR(__xludf.DUMMYFUNCTION("""COMPUTED_VALUE"""),"07.04 [IMG] [AD04] Pedidos abertos") -> 07.04 [IMG] [AD04] Pedidos abertos | J33: =IFERROR(__xludf.DUMMYFUNCTION("""COMPUTED_VALUE"""),"07.04.2026 [V4] [WB] [LEADS-GRUPO-WHATS] 01") -> 07.04.2026 [V4] [WB] [LEADS-GRUPO-WHATS] 01 | K33: =LEFT(A33,10) -> 2026-04-12 | L33: =DATE(YEAR(SUBSTITUTE(SUBSTITUTE(K33,"-","/",1),"-","/",1)),MONTH(SUBSTITUTE(SUBSTITUTE(K33,"-","/",1),"-","/",1)),DAY(SUBSTITUTE(SUBSTITUTE(K33,"-","/",1),"-","/",1))) -> 46124 | M33: =RIGHT(C33,8) -> 81595553 | N33: =IFERROR(IF(VLOOKUP(M33,'Leads no grupo Saibai'!C:C,1,FALSE)=M33,"Sim"),"Não") -> Sim
